Workbook

Sheet Заавар, журмын шаардлага
A1: 2 НАСТАЙ (БАГА БҮЛГИЙН) ХҮҮХДИЙН ГАРААНЫ (ОНОШЛОХ) ҮНЭЛГЭЭ: ЖУРМЫН ШААРДЛАГА
A3: № | B3: Шаардлага | C3: Агуулга | D3: Эх сурвалж
A4: 1 | B4: Мөрдөх журам | C4: Боловсролын сайдын 2026.03.11-ний А/79 тушаалаар батлагдсан «Сургуулийн өмнөх боловсролын үйлчилгээнд хамрагдаж байгаа суралцагчийн хөгжил болон сургуульд бэлтгэгдсэн байдлыг үнэлэх журам». 2020 оны А/280 тушаал хүчингүй болсон. | D4: А/79 тушаал, 1–4-р заалт
A5: 2 | B5: Үнэлгээний төрөл | C5: Суралцагчийн хөгжлийн үнэлгээ нь гараа (оношлох)-ны, явцын, үр дүнгийн гэсэн гурван төрөлтэй. | D5: А/79 журам 2.2
A6: 3 | B6: Хэн, хэзээ хийх | C6: Суралцагчийн хөгжлийн түвшин, ялгаатай хэрэгцээг тодорхойлж, сургалт, үйл ажиллагааг төлөвлөх зорилгоор гарааны үнэлгээг багш хичээлийн жилийн эхэнд хийнэ. | D6: А/79 журам 2.3
A7: 4 | B7: Бага бүлэгт баримтлах хөтөлбөр | C7: Бага бүлгийн суралцагчийн гарааны үнэлгээнд Сургуулийн өмнөх болон ерөнхий боловсролын тухай хуулийн 10.5-д заасан хөтөлбөр буюу «Гурав хүртэлх насны хүүхдийн цогц хөгжлийг дэмжих хөтөлбөр» (эрүүл мэнд, өсөлт, хэл яриа, танин мэдэхүйн хөгжлийг дэмжих баримт бичиг)-ийг баримтална. Дунд, ахлах, бэлтгэл бүлэгт өмнөх жилийн үр дүнгийн үнэлгээг ашиглана. | D7: А/79 журам 2.4, 2.5; Хуулийн 10.5
A8: 5 | B8: Шалгуур | C8: Энэ файлд А/79 журмын хавсралт «Суралцагчийн хөгжлийн үнэлгээний шалгуур»-ын I түвшний 37 шалгуурыг үг үсэг өөрчлөхгүй авсан: Мэдлэг 11, Чадвар 22, Төлөвшил 4. Журмын 1.2-т заасан бие бялдар, танин мэдэхүй, нийгэмшлийн хөгжлөөр шийтэд хуваасан (Бие бялдар 9, Танин мэдэхүй 19, Нийгэмшил 9). Шалгуурын №-ыг журмын хавсралтынхаар хадгалсан. | D8: А/79 журмын хавсралт, I түвшин; журам 1.2
A9: 6 | B9: СҮД-тэй уялдуулах | C9: Шалгуур бүрийн доор СӨБ-ын сургалтын хөтөлбөр (2025)-ийн I түвшний холбогдох суралцахуйн үр дүн (СҮД)-ийг код, эх бичвэрээр нь, түүний доор «Хүүхдийн хийх үйл» гэсэн ажиглах жишээ үйлийг нэг мөрөөр оруулсан. Хүүхдийн хийх үйлийн мөрийг багш бүлгийнхээ онцлогт тааруулан өөрчилж болно. | D9: СӨБ-ын сургалтын хөтөлбөр (2025)
A10: 7 | B10: Баримт нотолгоо | C10: Багш суралцагчийн суралцах үйл явцыг ажиглаж тэмдэглэл хөтөлнө; шаардлагатай үед ярилцлага хийж тэмдэглэнэ; баримт нотолгоо цуглуулж хувийн хавтас бүрдүүлнэ; суралцахуйн үр дүнд тулгуурласан «ажиглалтын хуудас»-ыг боловсруулж, мэргэжлийн багш нарын бүлгээр хэлэлцүүлэн сайжруулна. | D10: А/79 журам 2.8.1–2.8.5
A11: 8 | B11: Түвшин тогтоох | C11: Шалгуур хангасан хувиар: 80.0 ба түүнээс дээш «Хангалттай эзэмшиж байна»; 50.0–79.0 «Ахиж байна»; 49.0 ба түүнээс доош «Хөгжиж байна». Мэдлэг, чадвар, төлөвшлийн түвшнийг тус тусад нь тодорхойлно (Нэгтгэл шийтэд бодогдоно). | D11: А/79 журам 2.10
A12: 9 | B12: Зарчим | C12: Нас, хөгжлийн онцлог, ялгаатай хэрэгцээг харгалзсан, хүүхдийн хөгжлийг дэмжсэн, нотолгоонд суурилсан, оролцоог тэгш хангасан, ялгаварлан гадуурхалт, хөндлөнгийн нөлөөллөөс ангид байна. Хөгжлийн бэрхшээлтэй суралцагчид холбогдох журам, аргачлалыг баримтална. | D12: А/79 журам 1.3, 1.5
A13: 10 | B13: Ашиглах, мэдээлэх | C13: Үнэлгээний үр дүнг сургалт, үйл ажиллагааг төлөвлөх үндэслэл болгоно. Багш ахиц, хүрсэн үр дүнг эцэг эх, асран хамгаалагчид танилцуулж, зөвлөгөө өгч, хамтран ажиллана. Хувийн хавтсыг цэцэрлэгээс шилжих үед эцэг эхэд хүлээлгэн өгнө. | D13: А/79 журам 1.4, 2.14, 5.1
A14: 11 | B14: Хориглох зүйл | C14: Боловсролын эрдэм шинжилгээ, арга зүйн байгууллагын зөвшөөрөлгүйгээр суралцагчийн хөгжлийн түвшинг үнэлэх аливаа шалгалт, судалгаа авахыг хориглоно. Багш суралцагчийн үнэлгээг бусдад задруулахыг хориглоно. | D14: А/79 журам 5.3; Хуулийн 15.5
A15: 13 | B15: Цэцэрлэгийн үлгэрчилсэн дүрэм | C15: Цэцэрлэг 2–5 насны хүүхдийг хамруулж, бие бялдар, танин мэдэхүй, нийгэмшлийн хөгжлийг дэмжинэ (1.4, 1.5). Цэцэрлэг нь СӨБ-ын сургалтын хөтөлбөр болон хуулийн 10.5-д заасан гурав хүртэлх насны хүүхдийн цогц хөгжлийг дэмжих хөтөлбөрийг хэрэгжүүлнэ (7.6). Мэргэжлийн багш нарын бүлэг хүүхдийн хөгжлийн ахиц өөрчлөлтийг илрүүлэх, үнэлэх, дэмжлэг үзүүлэх асуудлыг хамтран хэлэлцэнэ (3.3.3.2) — А/79-ийн 2.8.4-ийн ажиглалтын хуудсыг энэ бүлгээр хэлэлцүүлнэ. Бага бүлэг 20 хүүхэдтэй (7.4.2). | D15: БШУ-ны сайдын 2023.12.25-ны А/569 «Хүүхдийн цэцэрлэгийн үлгэрчилсэн дүрэм»
... A19: 17 | B19: Хуулийн 10.5-ын 4 чиглэл | C19: Хуулийн тайлбараар гурав хүртэлх насны хүүхдийн цогц хөгжлийг дэмжих хөтөлбөр нь эрүүл мэнд, өсөлт, хэл яриа, танин мэдэхүйн хөгжлийг дэмжинэ. Хөтөлбөрийн бичвэр нийтэд олдоогүй тул А/79-ийн 37 шалгуурыг энэ файлд эдгээр 4 чиглэлд урьдчилан хуваарилсан, багш шалгаж засаж болно (шалгуурын толгойд «10.5: ...» гэж заасан): Эрүүл мэнд — 1, 2, 17, 18, 35, 36, 37; Өсөлт (бие бялдар, их ба нарийн хөдөлгөөн) — 12–16, 26, 28–30; Хэл яриа — 3, 11, 19–22, 31; Танин мэдэхүй — үлдсэн 14 шалгуур. Нэгтгэл шийтэд 4 чиглэл тус бүрийн хувь бодогдоно. Хөтөлбөр батлагдаж нийтлэгдвэл хуваарилалтыг тулгаж засна. | D19: Сургуулийн өмнөх болон ерөнхий боловсролын тухай хуулийн 10.5 ба түүний тайлбар; А/79 журам 2.4
A20: 18 | B20: Бөглөх заавар | C20: 1) «Нэгтгэл» шийтийн B баганад хүүхдийн нэрийг нэг удаа бичнэ; бусад шийтэд автоматаар гарна. 2) Шалгуур бүрийн «Чадна» эсвэл «Чадахгүй» нүдэнд 1 гэж бичнэ. 3) Тоо, хувь, түвшин, мэдлэг/чадвар/төлөвшлийн хувь автоматаар бодогдоно. 4) Шийт бүр A4-д хэвлэхэд тааруулсан.

Sheet Нэгтгэл
A1: ................ ЦЭЦЭРЛЭГИЙН БАГА БҮЛГИЙН (2 НАС) ГАРААНЫ (ОНОШЛОХ) ҮНЭЛГЭЭНИЙ НЭГТГЭЛ
A2: Огноо: 20.... оны .... сар Багш: ................................ Хүүхдийн нэрийг энэ шийтийн B баганад бичнэ.
A3: № | B3: Хүүхдийн нэр | C3: «Чадна» хувь (%) ба түвшин (А/79 журам 2.10) | M3: Нийт чадна (37-аас) | N3: Нийт хувь | O3: Түвшин
C4: Хөгжлийн чиглэл (%) | F4: Үнэлгээний хүрээ (%) | I4: Хуулийн 10.5-ын чиглэл (%)
C5: Бие бялдар | D5: Танин мэдэхүй | E5: Нийгэмшил | F5: Мэдлэг | G5: Чадвар | H5: Төлөвшил | I5: Эрүүл мэнд | J5: Өсөлт | K5: Хэл яриа | L5: Танин мэдэхүй
C6: 9 шалгуур | D6: 19 шалгуур | E6: 9 шалгуур | F6: 11 шалгуур | G6: 22 шалгуур | H6: 4 шалгуур | I6: 7 шалгуур | J6: 9 шалгуур | K6: 7 шалгуур | L6: 14 шалгуур
A7: 1 | C7: =IF(('Бие бялдар'!V10+'Бие бялдар'!X10+'Танин мэдэхүй'!AP10+'Танин мэдэхүй'!AR10+'Нийгэмшил'!V10+'Нийгэмшил'!X10)=0,"",ROUND(('Бие бялдар'!V10)/9*100,1)) | D7: =IF(('Бие бялдар'!V10+'Бие бялдар'!X10+'Танин мэдэхүй'!AP10+'Танин мэдэхүй'!AR10+'Нийгэмшил'!V10+'Нийгэмшил'!X10)=0,"",ROUND(('Танин мэдэхүй'!AP10)/19*100,1)) | E7: =IF(('Бие бялдар'!V10+'Бие бялдар'!X10+'Танин мэдэхүй'!AP10+'Танин мэдэхүй'!AR10+'Нийгэмшил'!V10+'Нийгэмшил'!X10)=0,"",ROUND(('Нийгэмшил'!V10)/9*100,1)) | F7: =IF(('Бие бялдар'!V10+'Бие бялдар'!X10+'Танин мэдэхүй'!AP10+'Танин мэдэхүй'!AR10+'Нийгэмшил'!V10+'Нийгэмшил'!X10)=0,"",ROUND((N('Бие бялдар'!D10)+N('Бие бялдар'!F10)+N('Танин мэдэхүй'!D10)+N('Танин мэдэхүй'!F10)+N('Танин мэдэхүй'!H10)+N('Танин мэдэхүй'!J10)+N('Нийгэмшил'!D10)+N('Танин мэдэхүй'!L10)+N('Танин мэдэхүй'!N10)+N('Нийгэмшил'!F10)+N('Нийгэмшил'!H10))/11*100,1)) | G7: =IF(('Бие бялдар'!V10+'Бие бялдар'!X10+'Танин мэдэхүй'!AP10+'Танин мэдэхүй'!AR10+'Нийгэмшил'!V10+'Нийгэмшил'!X10)=0,"",ROUND((N('Бие бялдар'!H10)+N('Бие бялдар'!J10)+N('Бие бялдар'!L10)+N('Бие бялдар'!N10)+N('Бие бялдар'!P10)+N('Бие бялдар'!R10)+N('Бие бялдар'!T10)+N('Танин мэдэхүй'!P10)+N('Танин мэдэхүй'!R10)+N('Танин мэдэхүй'!T10)+N('Танин мэдэхүй'!V10)+N('Танин мэдэхүй'!X10)+N('Танин мэдэхүй'!Z10)+N('Танин мэдэхүй'!AB10)+N('Танин мэдэхүй'!AD10)+N('Нийгэмшил'!J10)+N('Танин мэдэхүй'!AF10)+N('Танин мэдэхүй'!AH10)+N('Танин мэдэхүй'!AJ10)+N('Нийгэмшил'!L10)+N('Танин мэдэхүй'!AL10)+N('Танин мэдэхүй'!AN10))/22*100,1)) | H7: =IF(('Бие бялдар'!V10+'Бие бялдар'!X10+'Танин мэдэхүй'!AP10+'Танин мэдэхүй'!AR10+'Нийгэмшил'!V10+'Нийгэмшил'!X10)=0,"",ROUND((N('Нийгэмшил'!N10)+N('Нийгэмшил'!P10)+N('Нийгэмшил'!R10)+N('Нийгэмшил'!T10))/4*100,1)) | I7: =IF(('Бие бялдар'!V10+'Бие бялдар'!X10+'Танин мэдэхүй'!AP10+'Танин мэдэхүй'!AR10+'Нийгэмшил'!V10+'Нийгэмшил'!X10)=0,"",ROUND((N('Бие бялдар'!D10)+N('Бие бялдар'!F10)+N('Бие бялдар'!R10)+N('Бие бялдар'!T10)+N('Нийгэмшил'!P10)+N('Нийгэмшил'!R10)+N('Нийгэмшил'!T10))/7*100,1)) | J7: =IF(('Бие бялдар'!V10+'Бие бялдар'!X10+'Танин мэдэхүй'!AP10+'Танин мэдэхүй'!AR10+'Нийгэмшил'!V10+'Нийгэмшил'!X10)=0,"",ROUND((N('Бие бялдар'!H10)+N('Бие бялдар'!J10)+N('Бие бялдар'!L10)+N('Бие бялдар'!N10)+N('Бие бялдар'!P10)+N('Танин мэдэхүй'!AD10)+N('Танин мэдэхүй'!AF10)+N('Танин мэдэхүй'!AH10)+N('Танин мэдэхүй'!AJ10))/9*100,1)) | K7: =IF(('Бие бялдар'!V10+'Бие бялдар'!X10+'Танин мэдэхүй'!AP10+'Танин мэдэхүй'!AR10+'Нийгэмшил'!V10+'Нийгэмшил'!X10)=0,"",ROUND((N('Танин мэдэхүй'!D10)+N('Нийгэмшил'!H10)+N('Танин мэдэхүй'!P10)+N('Танин мэдэхүй'!R10)+N('Танин мэдэхүй'!T10)+N('Танин мэдэхүй'!V10)+N('Нийгэмшил'!L10))/7*100,1)) | L7: =IF(('Бие бялдар'!V10+'Бие бялдар'!X10+'Танин мэдэхүй'!AP10+'Танин мэдэхүй'!AR10+'Нийгэмшил'!V10+'Нийгэмшил'!X10)=0,"",ROUND((N('Танин мэдэхүй'!F10)+N('Танин мэдэхүй'!H10)+N('Танин мэдэхүй'!J10)+N('Нийгэмшил'!D10)+N('Танин мэдэхүй'!L10)+N('Танин мэдэхүй'!N10)+N('Нийгэмшил'!F10)+N('Танин мэдэхүй'!X10)+N('Танин мэдэхүй'!Z10)+N('Танин мэдэхүй'!AB10)+N('Нийгэмшил'!J10)+N('Танин мэдэхүй'!AL10)+N('Танин мэдэхүй'!AN10)+N('Нийгэмшил'!N10))/14*100,1)) | M7: ='Бие бялдар'!V10+'Танин мэдэхүй'!AP10+'Нийгэмшил'!V10 | N7: =IF(('Бие бялдар'!V10+'Бие бялдар'!X10+'Танин мэдэхүй'!AP10+'Танин мэдэхүй'!AR10+'Нийгэмшил'!V10+'Нийгэмшил'!X10)=0,"",ROUND(M7/37*100,1)) | O7: =IF(N7="","",IF(N7>=80,"Хангалттай эзэмшиж байна",IF(N7>=50,"Ахиж байна","Хөгжиж байна")))
A8: 2 | C8: =IF(('Бие бялдар'!V11+'Бие бялдар'!X11+'Танин мэдэхүй'!AP11+'Танин мэдэхүй'!AR11+'Нийгэмшил'!V11+'Нийгэмшил'!X11)=0,"",ROUND(('Бие бялдар'!V11)/9*100,1)) | D8: =IF(('Бие бялдар'!V11+'Бие бялдар'!X11+'Танин мэдэхүй'!AP11+'Танин мэдэхүй'!AR11+'Нийгэмшил'!V11+'Нийгэмшил'!X11)=0,"",ROUND(('Танин мэдэхүй'!AP11)/19*100,1)) | E8: =IF(('Бие бялдар'!V11+'Бие бялдар'!X11+'Танин мэдэхүй'!AP11+'Танин мэдэхүй'!AR11+'Нийгэмшил'!V11+'Нийгэмшил'!X11)=0,"",ROUND(('Нийгэмшил'!V11)/9*100,1)) | F8: =IF(('Бие бялдар'!V11+'Бие бялдар'!X11+'Танин мэдэхүй'!AP11+'Танин мэдэхүй'!AR11+'Нийгэмшил'!V11+'Нийгэмшил'!X11)=0,"",ROUND((N('Бие бялдар'!D11)+N('Бие бялдар'!F11)+N('Танин мэдэхүй'!D11)+N('Танин мэдэхүй'!F11)+N('Танин мэдэхүй'!H11)+N('Танин мэдэхүй'!J11)+N('Нийгэмшил'!D11)+N('Танин мэдэхүй'!L11)+N('Танин мэдэхүй'!N11)+N('Нийгэмшил'!F11)+N('Нийгэмшил'!H11))/11*100,1)) | G8: =IF(('Бие бялдар'!V11+'Бие бялдар'!X11+'Танин мэдэхүй'!AP11+'Танин мэдэхүй'!AR11+'Нийгэмшил'!V11+'Нийгэмшил'!X11)=0,"",ROUND((N('Бие бялдар'!H11)+N('Бие бялдар'!J11)+N('Бие бялдар'!L11)+N('Бие бялдар'!N11)+N('Бие бялдар'!P11)+N('Бие бялдар'!R11)+N('Бие бялдар'!T11)+N('Танин мэдэхүй'!P11)+N('Танин мэдэхүй'!R11)+N('Танин мэдэхүй'!T11)+N('Танин мэдэхүй'!V11)+N('Танин мэдэхүй'!X11)+N('Танин мэдэхүй'!Z11)+N('Танин мэдэхүй'!AB11)+N('Танин мэдэхүй'!AD11)+N('Нийгэмшил'!J11)+N('Танин мэдэхүй'!AF11)+N('Танин мэдэхүй'!AH11)+N('Танин мэдэхүй'!AJ11)+N('Нийгэмшил'!L11)+N('Танин мэдэхүй'!AL11)+N('Танин мэдэхүй'!AN11))/22*100,1)) | H8: =IF(('Бие бялдар'!V11+'Бие бялдар'!X11+'Танин мэдэхүй'!AP11+'Танин мэдэхүй'!AR11+'Нийгэмшил'!V11+'Нийгэмшил'!X11)=0,"",ROUND((N('Нийгэмшил'!N11)+N('Нийгэмшил'!P11)+N('Нийгэмшил'!R11)+N('Нийгэмшил'!T11))/4*100,1)) | I8: =IF(('Бие бялдар'!V11+'Бие бялдар'!X11+'Танин мэдэхүй'!AP11+'Танин мэдэхүй'!AR11+'Нийгэмшил'!V11+'Нийгэмшил'!X11)=0,"",ROUND((N('Бие бялдар'!D11)+N('Бие бялдар'!F11)+N('Бие бялдар'!R11)+N('Бие бялдар'!T11)+N('Нийгэмшил'!P11)+N('Нийгэмшил'!R11)+N('Нийгэмшил'!T11))/7*100,1)) | J8: =IF(('Бие бялдар'!V11+'Бие бялдар'!X11+'Танин мэдэхүй'!AP11+'Танин мэдэхүй'!AR11+'Нийгэмшил'!V11+'Нийгэмшил'!X11)=0,"",ROUND((N('Бие бялдар'!H11)+N('Бие бялдар'!J11)+N('Бие бялдар'!L11)+N('Бие бялдар'!N11)+N('Бие бялдар'!P11)+N('Танин мэдэхүй'!AD11)+N('Танин мэдэхүй'!AF11)+N('Танин мэдэхүй'!AH11)+N('Танин мэдэхүй'!AJ11))/9*100,1)) | K8: =IF(('Бие бялдар'!V11+'Бие бялдар'!X11+'Танин мэдэхүй'!AP11+'Танин мэдэхүй'!AR11+'Нийгэмшил'!V11+'Нийгэмшил'!X11)=0,"",ROUND((N('Танин мэдэхүй'!D11)+N('Нийгэмшил'!H11)+N('Танин мэдэхүй'!P11)+N('Танин мэдэхүй'!R11)+N('Танин мэдэхүй'!T11)+N('Танин мэдэхүй'!V11)+N('Нийгэмшил'!L11))/7*100,1)) | L8: =IF(('Бие бялдар'!V11+'Бие бялдар'!X11+'Танин мэдэхүй'!AP11+'Танин мэдэхүй'!AR11+'Нийгэмшил'!V11+'Нийгэмшил'!X11)=0,"",ROUND((N('Танин мэдэхүй'!F11)+N('Танин мэдэхүй'!H11)+N('Танин мэдэхүй'!J11)+N('Нийгэмшил'!D11)+N('Танин мэдэхүй'!L11)+N('Танин мэдэхүй'!N11)+N('Нийгэмшил'!F11)+N('Танин мэдэхүй'!X11)+N('Танин мэдэхүй'!Z11)+N('Танин мэдэхүй'!AB11)+N('Нийгэмшил'!J11)+N('Танин мэдэхүй'!AL11)+N('Танин мэдэхүй'!AN11)+N('Нийгэмшил'!N11))/14*100,1)) | M8: ='Бие бялдар'!V11+'Танин мэдэхүй'!AP11+'Нийгэмшил'!V11 | N8: =IF(('Бие бялдар'!V11+'Бие бялдар'!X11+'Танин мэдэхүй'!AP11+'Танин мэдэхүй'!AR11+'Нийгэмшил'!V11+'Нийгэмшил'!X11)=0,"",ROUND(M8/37*100,1)) | O8: =IF(N8="","",IF(N8>=80,"Хангалттай эзэмшиж байна",IF(N8>=50,"Ахиж байна","Хөгжиж байна")))
A9: 3 | C9: =IF(('Бие бялдар'!V12+'Бие бялдар'!X12+'Танин мэдэхүй'!AP12+'Танин мэдэхүй'!AR12+'Нийгэмшил'!V12+'Нийгэмшил'!X12)=0,"",ROUND(('Бие бялдар'!V12)/9*100,1)) | D9: =IF(('Бие бялдар'!V12+'Бие бялдар'!X12+'Танин мэдэхүй'!AP12+'Танин мэдэхүй'!AR12+'Нийгэмшил'!V12+'Нийгэмшил'!X12)=0,"",ROUND(('Танин мэдэхүй'!AP12)/19*100,1)) | E9: =IF(('Бие бялдар'!V12+'Бие бялдар'!X12+'Танин мэдэхүй'!AP12+'Танин мэдэхүй'!AR12+'Нийгэмшил'!V12+'Нийгэмшил'!X12)=0,"",ROUND(('Нийгэмшил'!V12)/9*100,1)) | F9: =IF(('Бие бялдар'!V12+'Бие бялдар'!X12+'Танин мэдэхүй'!AP12+'Танин мэдэхүй'!AR12+'Нийгэмшил'!V12+'Нийгэмшил'!X12)=0,"",ROUND((N('Бие бялдар'!D12)+N('Бие бялдар'!F12)+N('Танин мэдэхүй'!D12)+N('Танин мэдэхүй'!F12)+N('Танин мэдэхүй'!H12)+N('Танин мэдэхүй'!J12)+N('Нийгэмшил'!D12)+N('Танин мэдэхүй'!L12)+N('Танин мэдэхүй'!N12)+N('Нийгэмшил'!F12)+N('Нийгэмшил'!H12))/11*100,1)) | G9: =IF(('Бие бялдар'!V12+'Бие бялдар'!X12+'Танин мэдэхүй'!AP12+'Танин мэдэхүй'!AR12+'Нийгэмшил'!V12+'Нийгэмшил'!X12)=0,"",ROUND((N('Бие бялдар'!H12)+N('Бие бялдар'!J12)+N('Бие бялдар'!L12)+N('Бие бялдар'!N12)+N('Бие бялдар'!P12)+N('Бие бялдар'!R12)+N('Бие бялдар'!T12)+N('Танин мэдэхүй'!P12)+N('Танин мэдэхүй'!R12)+N('Танин мэдэхүй'!T12)+N('Танин мэдэхүй'!V12)+N('Танин мэдэхүй'!X12)+N('Танин мэдэхүй'!Z12)+N('Танин мэдэхүй'!AB12)+N('Танин мэдэхүй'!AD12)+N('Нийгэмшил'!J12)+N('Танин мэдэхүй'!AF12)+N('Танин мэдэхүй'!AH12)+N('Танин мэдэхүй'!AJ12)+N('Нийгэмшил'!L12)+N('Танин мэдэхүй'!AL12)+N('Танин мэдэхүй'!AN12))/22*100,1)) | H9: =IF(('Бие бялдар'!V12+'Бие бялдар'!X12+'Танин мэдэхүй'!AP12+'Танин мэдэхүй'!AR12+'Нийгэмшил'!V12+'Нийгэмшил'!X12)=0,"",ROUND((N('Нийгэмшил'!N12)+N('Нийгэмшил'!P12)+N('Нийгэмшил'!R12)+N('Нийгэмшил'!T12))/4*100,1)) | I9: =IF(('Бие бялдар'!V12+'Бие бялдар'!X12+'Танин мэдэхүй'!AP12+'Танин мэдэхүй'!AR12+'Нийгэмшил'!V12+'Нийгэмшил'!X12)=0,"",ROUND((N('Бие бялдар'!D12)+N('Бие бялдар'!F12)+N('Бие бялдар'!R12)+N('Бие бялдар'!T12)+N('Нийгэмшил'!P12)+N('Нийгэмшил'!R12)+N('Нийгэмшил'!T12))/7*100,1)) | J9: =IF(('Бие бялдар'!V12+'Бие бялдар'!X12+'Танин мэдэхүй'!AP12+'Танин мэдэхүй'!AR12+'Нийгэмшил'!V12+'Нийгэмшил'!X12)=0,"",ROUND((N('Бие бялдар'!H12)+N('Бие бялдар'!J12)+N('Бие бялдар'!L12)+N('Бие бялдар'!N12)+N('Бие бялдар'!P12)+N('Танин мэдэхүй'!AD12)+N('Танин мэдэхүй'!AF12)+N('Танин мэдэхүй'!AH12)+N('Танин мэдэхүй'!AJ12))/9*100,1)) | K9: =IF(('Бие бялдар'!V12+'Бие бялдар'!X12+'Танин мэдэхүй'!AP12+'Танин мэдэхүй'!AR12+'Нийгэмшил'!V12+'Нийгэмшил'!X12)=0,"",ROUND((N('Танин мэдэхүй'!D12)+N('Нийгэмшил'!H12)+N('Танин мэдэхүй'!P12)+N('Танин мэдэхүй'!R12)+N('Танин мэдэхүй'!T12)+N('Танин мэдэхүй'!V12)+N('Нийгэмшил'!L12))/7*100,1)) | L9: =IF(('Бие бялдар'!V12+'Бие бялдар'!X12+'Танин мэдэхүй'!AP12+'Танин мэдэхүй'!AR12+'Нийгэмшил'!V12+'Нийгэмшил'!X12)=0,"",ROUND((N('Танин мэдэхүй'!F12)+N('Танин мэдэхүй'!H12)+N('Танин мэдэхүй'!J12)+N('Нийгэмшил'!D12)+N('Танин мэдэхүй'!L12)+N('Танин мэдэхүй'!N12)+N('Нийгэмшил'!F12)+N('Танин мэдэхүй'!X12)+N('Танин мэдэхүй'!Z12)+N('Танин мэдэхүй'!AB12)+N('Нийгэмшил'!J12)+N('Танин мэдэхүй'!AL12)+N('Танин мэдэхүй'!AN12)+N('Нийгэмшил'!N12))/14*100,1)) | M9: ='Бие бялдар'!V12+'Танин мэдэхүй'!AP12+'Нийгэмшил'!V12 | N9: =IF(('Бие бялдар'!V12+'Бие бялдар'!X12+'Танин мэдэхүй'!AP12+'Танин мэдэхүй'!AR12+'Нийгэмшил'!V12+'Нийгэмшил'!X12)=0,"",ROUND(M9/37*100,1)) | O9: =IF(N9="","",IF(N9>=80,"Хангалттай эзэмшиж байна",IF(N9>=50,"Ахиж байна","Хөгжиж байна")))
A10: 4 | C10: =IF(('Бие бялдар'!V13+'Бие бялдар'!X13+'Танин мэдэхүй'!AP13+'Танин мэдэхүй'!AR13+'Нийгэмшил'!V13+'Нийгэмшил'!X13)=0,"",ROUND(('Бие бялдар'!V13)/9*100,1)) | D10: =IF(('Бие бялдар'!V13+'Бие бялдар'!X13+'Танин мэдэхүй'!AP13+'Танин мэдэхүй'!AR13+'Нийгэмшил'!V13+'Нийгэмшил'!X13)=0,"",ROUND(('Танин мэдэхүй'!AP13)/19*100,1)) | E10: =IF(('Бие бялдар'!V13+'Бие бялдар'!X13+'Танин мэдэхүй'!AP13+'Танин мэдэхүй'!AR13+'Нийгэмшил'!V13+'Нийгэмшил'!X13)=0,"",ROUND(('Нийгэмшил'!V13)/9*100,1)) | F10: =IF(('Бие бялдар'!V13+'Бие бялдар'!X13+'Танин мэдэхүй'!AP13+'Танин мэдэхүй'!AR13+'Нийгэмшил'!V13+'Нийгэмшил'!X13)=0,"",ROUND((N('Бие бялдар'!D13)+N('Бие бялдар'!F13)+N('Танин мэдэхүй'!D13)+N('Танин мэдэхүй'!F13)+N('Танин мэдэхүй'!H13)+N('Танин мэдэхүй'!J13)+N('Нийгэмшил'!D13)+N('Танин мэдэхүй'!L13)+N('Танин мэдэхүй'!N13)+N('Нийгэмшил'!F13)+N('Нийгэмшил'!H13))/11*100,1)) | G10: =IF(('Бие бялдар'!V13+'Бие бялдар'!X13+'Танин мэдэхүй'!AP13+'Танин мэдэхүй'!AR13+'Нийгэмшил'!V13+'Нийгэмшил'!X13)=0,"",ROUND((N('Бие бялдар'!H13)+N('Бие бялдар'!J13)+N('Бие бялдар'!L13)+N('Бие бялдар'!N13)+N('Бие бялдар'!P13)+N('Бие бялдар'!R13)+N('Бие бялдар'!T13)+N('Танин мэдэхүй'!P13)+N('Танин мэдэхүй'!R13)+N('Танин мэдэхүй'!T13)+N('Танин мэдэхүй'!V13)+N('Танин мэдэхүй'!X13)+N('Танин мэдэхүй'!Z13)+N('Танин мэдэхүй'!AB13)+N('Танин мэдэхүй'!AD13)+N('Нийгэмшил'!J13)+N('Танин мэдэхүй'!AF13)+N('Танин мэдэхүй'!AH13)+N('Танин мэдэхүй'!AJ13)+N('Нийгэмшил'!L13)+N('Танин мэдэхүй'!AL13)+N('Танин мэдэхүй'!AN13))/22*100,1)) | H10: =IF(('Бие бялдар'!V13+'Бие бялдар'!X13+'Танин мэдэхүй'!AP13+'Танин мэдэхүй'!AR13+'Нийгэмшил'!V13+'Нийгэмшил'!X13)=0,"",ROUND((N('Нийгэмшил'!N13)+N('Нийгэмшил'!P13)+N('Нийгэмшил'!R13)+N('Нийгэмшил'!T13))/4*100,1)) | I10: =IF(('Бие бялдар'!V13+'Бие бялдар'!X13+'Танин мэдэхүй'!AP13+'Танин мэдэхүй'!AR13+'Нийгэмшил'!V13+'Нийгэмшил'!X13)=0,"",ROUND((N('Бие бялдар'!D13)+N('Бие бялдар'!F13)+N('Бие бялдар'!R13)+N('Бие бялдар'!T13)+N('Нийгэмшил'!P13)+N('Нийгэмшил'!R13)+N('Нийгэмшил'!T13))/7*100,1)) | J10: =IF(('Бие бялдар'!V13+'Бие бялдар'!X13+'Танин мэдэхүй'!AP13+'Танин мэдэхүй'!AR13+'Нийгэмшил'!V13+'Нийгэмшил'!X13)=0,"",ROUND((N('Бие бялдар'!H13)+N('Бие бялдар'!J13)+N('Бие бялдар'!L13)+N('Бие бялдар'!N13)+N('Бие бялдар'!P13)+N('Танин мэдэхүй'!AD13)+N('Танин мэдэхүй'!AF13)+N('Танин мэдэхүй'!AH13)+N('Танин мэдэхүй'!AJ13))/9*100,1)) | K10: =IF(('Бие бялдар'!V13+'Бие бялдар'!X13+'Танин мэдэхүй'!AP13+'Танин мэдэхүй'!AR13+'Нийгэмшил'!V13+'Нийгэмшил'!X13)=0,"",ROUND((N('Танин мэдэхүй'!D13)+N('Нийгэмшил'!H13)+N('Танин мэдэхүй'!P13)+N('Танин мэдэхүй'!R13)+N('Танин мэдэхүй'!T13)+N('Танин мэдэхүй'!V13)+N('Нийгэмшил'!L13))/7*100,1)) | L10: =IF(('Бие бялдар'!V13+'Бие бялдар'!X13+'Танин мэдэхүй'!AP13+'Танин мэдэхүй'!AR13+'Нийгэмшил'!V13+'Нийгэмшил'!X13)=0,"",ROUND((N('Танин мэдэхүй'!F13)+N('Танин мэдэхүй'!H13)+N('Танин мэдэхүй'!J13)+N('Нийгэмшил'!D13)+N('Танин мэдэхүй'!L13)+N('Танин мэдэхүй'!N13)+N('Нийгэмшил'!F13)+N('Танин мэдэхүй'!X13)+N('Танин мэдэхүй'!Z13)+N('Танин мэдэхүй'!AB13)+N('Нийгэмшил'!J13)+N('Танин мэдэхүй'!AL13)+N('Танин мэдэхүй'!AN13)+N('Нийгэмшил'!N13))/14*100,1)) | M10: ='Бие бялдар'!V13+'Танин мэдэхүй'!AP13+'Нийгэмшил'!V13 | N10: =IF(('Бие бялдар'!V13+'Бие бялдар'!X13+'Танин мэдэхүй'!AP13+'Танин мэдэхүй'!AR13+'Нийгэмшил'!V13+'Нийгэмшил'!X13)=0,"",ROUND(M10/37*100,1)) | O10: =IF(N10="","",IF(N10>=80,"Хангалттай эзэмшиж байна",IF(N10>=50,"Ахиж байна","Хөгжиж байна")))
A11: 5 | C11: =IF(('Бие бялдар'!V14+'Бие бялдар'!X14+'Танин мэдэхүй'!AP14+'Танин мэдэхүй'!AR14+'Нийгэмшил'!V14+'Нийгэмшил'!X14)=0,"",ROUND(('Бие бялдар'!V14)/9*100,1)) | D11: =IF(('Бие бялдар'!V14+'Бие бялдар'!X14+'Танин мэдэхүй'!AP14+'Танин мэдэхүй'!AR14+'Нийгэмшил'!V14+'Нийгэмшил'!X14)=0,"",ROUND(('Танин мэдэхүй'!AP14)/19*100,1)) | E11: =IF(('Бие бялдар'!V14+'Бие бялдар'!X14+'Танин мэдэхүй'!AP14+'Танин мэдэхүй'!AR14+'Нийгэмшил'!V14+'Нийгэмшил'!X14)=0,"",ROUND(('Нийгэмшил'!V14)/9*100,1)) | F11: =IF(('Бие бялдар'!V14+'Бие бялдар'!X14+'Танин мэдэхүй'!AP14+'Танин мэдэхүй'!AR14+'Нийгэмшил'!V14+'Нийгэмшил'!X14)=0,"",ROUND((N('Бие бялдар'!D14)+N('Бие бялдар'!F14)+N('Танин мэдэхүй'!D14)+N('Танин мэдэхүй'!F14)+N('Танин мэдэхүй'!H14)+N('Танин мэдэхүй'!J14)+N('Нийгэмшил'!D14)+N('Танин мэдэхүй'!L14)+N('Танин мэдэхүй'!N14)+N('Нийгэмшил'!F14)+N('Нийгэмшил'!H14))/11*100,1)) | G11: =IF(('Бие бялдар'!V14+'Бие бялдар'!X14+'Танин мэдэхүй'!AP14+'Танин мэдэхүй'!AR14+'Нийгэмшил'!V14+'Нийгэмшил'!X14)=0,"",ROUND((N('Бие бялдар'!H14)+N('Бие бялдар'!J14)+N('Бие бялдар'!L14)+N('Бие бялдар'!N14)+N('Бие бялдар'!P14)+N('Бие бялдар'!R14)+N('Бие бялдар'!T14)+N('Танин мэдэхүй'!P14)+N('Танин мэдэхүй'!R14)+N('Танин мэдэхүй'!T14)+N('Танин мэдэхүй'!V14)+N('Танин мэдэхүй'!X14)+N('Танин мэдэхүй'!Z14)+N('Танин мэдэхүй'!AB14)+N('Танин мэдэхүй'!AD14)+N('Нийгэмшил'!J14)+N('Танин мэдэхүй'!AF14)+N('Танин мэдэхүй'!AH14)+N('Танин мэдэхүй'!AJ14)+N('Нийгэмшил'!L14)+N('Танин мэдэхүй'!AL14)+N('Танин мэдэхүй'!AN14))/22*100,1)) | H11: =IF(('Бие бялдар'!V14+'Бие бялдар'!X14+'Танин мэдэхүй'!AP14+'Танин мэдэхүй'!AR14+'Нийгэмшил'!V14+'Нийгэмшил'!X14)=0,"",ROUND((N('Нийгэмшил'!N14)+N('Нийгэмшил'!P14)+N('Нийгэмшил'!R14)+N('Нийгэмшил'!T14))/4*100,1)) | I11: =IF(('Бие бялдар'!V14+'Бие бялдар'!X14+'Танин мэдэхүй'!AP14+'Танин мэдэхүй'!AR14+'Нийгэмшил'!V14+'Нийгэмшил'!X14)=0,"",ROUND((N('Бие бялдар'!D14)+N('Бие бялдар'!F14)+N('Бие бялдар'!R14)+N('Бие бялдар'!T14)+N('Нийгэмшил'!P14)+N('Нийгэмшил'!R14)+N('Нийгэмшил'!T14))/7*100,1)) | J11: =IF(('Бие бялдар'!V14+'Бие бялдар'!X14+'Танин мэдэхүй'!AP14+'Танин мэдэхүй'!AR14+'Нийгэмшил'!V14+'Нийгэмшил'!X14)=0,"",ROUND((N('Бие бялдар'!H14)+N('Бие бялдар'!J14)+N('Бие бялдар'!L14)+N('Бие бялдар'!N14)+N('Бие бялдар'!P14)+N('Танин мэдэхүй'!AD14)+N('Танин мэдэхүй'!AF14)+N('Танин мэдэхүй'!AH14)+N('Танин мэдэхүй'!AJ14))/9*100,1)) | K11: =IF(('Бие бялдар'!V14+'Бие бялдар'!X14+'Танин мэдэхүй'!AP14+'Танин мэдэхүй'!AR14+'Нийгэмшил'!V14+'Нийгэмшил'!X14)=0,"",ROUND((N('Танин мэдэхүй'!D14)+N('Нийгэмшил'!H14)+N('Танин мэдэхүй'!P14)+N('Танин мэдэхүй'!R14)+N('Танин мэдэхүй'!T14)+N('Танин мэдэхүй'!V14)+N('Нийгэмшил'!L14))/7*100,1)) | L11: =IF(('Бие бялдар'!V14+'Бие бялдар'!X14+'Танин мэдэхүй'!AP14+'Танин мэдэхүй'!AR14+'Нийгэмшил'!V14+'Нийгэмшил'!X14)=0,"",ROUND((N('Танин мэдэхүй'!F14)+N('Танин мэдэхүй'!H14)+N('Танин мэдэхүй'!J14)+N('Нийгэмшил'!D14)+N('Танин мэдэхүй'!L14)+N('Танин мэдэхүй'!N14)+N('Нийгэмшил'!F14)+N('Танин мэдэхүй'!X14)+N('Танин мэдэхүй'!Z14)+N('Танин мэдэхүй'!AB14)+N('Нийгэмшил'!J14)+N('Танин мэдэхүй'!AL14)+N('Танин мэдэхүй'!AN14)+N('Нийгэмшил'!N14))/14*100,1)) | M11: ='Бие бялдар'!V14+'Танин мэдэхүй'!AP14+'Нийгэмшил'!V14 | N11: =IF(('Бие бялдар'!V14+'Бие бялдар'!X14+'Танин мэдэхүй'!AP14+'Танин мэдэхүй'!AR14+'Нийгэмшил'!V14+'Нийгэмшил'!X14)=0,"",ROUND(M11/37*100,1)) | O11: =IF(N11="","",IF(N11>=80,"Хангалттай эзэмшиж байна",IF(N11>=50,"Ахиж байна","Хөгжиж байна")))
A12: 6 | C12: =IF(('Бие бялдар'!V15+'Бие бялдар'!X15+'Танин мэдэхүй'!AP15+'Танин мэдэхүй'!AR15+'Нийгэмшил'!V15+'Нийгэмшил'!X15)=0,"",ROUND(('Бие бялдар'!V15)/9*100,1)) | D12: =IF(('Бие бялдар'!V15+'Бие бялдар'!X15+'Танин мэдэхүй'!AP15+'Танин мэдэхүй'!AR15+'Нийгэмшил'!V15+'Нийгэмшил'!X15)=0,"",ROUND(('Танин мэдэхүй'!AP15)/19*100,1)) | E12: =IF(('Бие бялдар'!V15+'Бие бялдар'!X15+'Танин мэдэхүй'!AP15+'Танин мэдэхүй'!AR15+'Нийгэмшил'!V15+'Нийгэмшил'!X15)=0,"",ROUND(('Нийгэмшил'!V15)/9*100,1)) | F12: =IF(('Бие бялдар'!V15+'Бие бялдар'!X15+'Танин мэдэхүй'!AP15+'Танин мэдэхүй'!AR15+'Нийгэмшил'!V15+'Нийгэмшил'!X15)=0,"",ROUND((N('Бие бялдар'!D15)+N('Бие бялдар'!F15)+N('Танин мэдэхүй'!D15)+N('Танин мэдэхүй'!F15)+N('Танин мэдэхүй'!H15)+N('Танин мэдэхүй'!J15)+N('Нийгэмшил'!D15)+N('Танин мэдэхүй'!L15)+N('Танин мэдэхүй'!N15)+N('Нийгэмшил'!F15)+N('Нийгэмшил'!H15))/11*100,1)) | G12: =IF(('Бие бялдар'!V15+'Бие бялдар'!X15+'Танин мэдэхүй'!AP15+'Танин мэдэхүй'!AR15+'Нийгэмшил'!V15+'Нийгэмшил'!X15)=0,"",ROUND((N('Бие бялдар'!H15)+N('Бие бялдар'!J15)+N('Бие бялдар'!L15)+N('Бие бялдар'!N15)+N('Бие бялдар'!P15)+N('Бие бялдар'!R15)+N('Бие бялдар'!T15)+N('Танин мэдэхүй'!P15)+N('Танин мэдэхүй'!R15)+N('Танин мэдэхүй'!T15)+N('Танин мэдэхүй'!V15)+N('Танин мэдэхүй'!X15)+N('Танин мэдэхүй'!Z15)+N('Танин мэдэхүй'!AB15)+N('Танин мэдэхүй'!AD15)+N('Нийгэмшил'!J15)+N('Танин мэдэхүй'!AF15)+N('Танин мэдэхүй'!AH15)+N('Танин мэдэхүй'!AJ15)+N('Нийгэмшил'!L15)+N('Танин мэдэхүй'!AL15)+N('Танин мэдэхүй'!AN15))/22*100,1)) | H12: =IF(('Бие бялдар'!V15+'Бие бялдар'!X15+'Танин мэдэхүй'!AP15+'Танин мэдэхүй'!AR15+'Нийгэмшил'!V15+'Нийгэмшил'!X15)=0,"",ROUND((N('Нийгэмшил'!N15)+N('Нийгэмшил'!P15)+N('Нийгэмшил'!R15)+N('Нийгэмшил'!T15))/4*100,1)) | I12: =IF(('Бие бялдар'!V15+'Бие бялдар'!X15+'Танин мэдэхүй'!AP15+'Танин мэдэхүй'!AR15+'Нийгэмшил'!V15+'Нийгэмшил'!X15)=0,"",ROUND((N('Бие бялдар'!D15)+N('Бие бялдар'!F15)+N('Бие бялдар'!R15)+N('Бие бялдар'!T15)+N('Нийгэмшил'!P15)+N('Нийгэмшил'!R15)+N('Нийгэмшил'!T15))/7*100,1)) | J12: =IF(('Бие бялдар'!V15+'Бие бялдар'!X15+'Танин мэдэхүй'!AP15+'Танин мэдэхүй'!AR15+'Нийгэмшил'!V15+'Нийгэмшил'!X15)=0,"",ROUND((N('Бие бялдар'!H15)+N('Бие бялдар'!J15)+N('Бие бялдар'!L15)+N('Бие бялдар'!N15)+N('Бие бялдар'!P15)+N('Танин мэдэхүй'!AD15)+N('Танин мэдэхүй'!AF15)+N('Танин мэдэхүй'!AH15)+N('Танин мэдэхүй'!AJ15))/9*100,1)) | K12: =IF(('Бие бялдар'!V15+'Бие бялдар'!X15+'Танин мэдэхүй'!AP15+'Танин мэдэхүй'!AR15+'Нийгэмшил'!V15+'Нийгэмшил'!X15)=0,"",ROUND((N('Танин мэдэхүй'!D15)+N('Нийгэмшил'!H15)+N('Танин мэдэхүй'!P15)+N('Танин мэдэхүй'!R15)+N('Танин мэдэхүй'!T15)+N('Танин мэдэхүй'!V15)+N('Нийгэмшил'!L15))/7*100,1)) | L12: =IF(('Бие бялдар'!V15+'Бие бялдар'!X15+'Танин мэдэхүй'!AP15+'Танин мэдэхүй'!AR15+'Нийгэмшил'!V15+'Нийгэмшил'!X15)=0,"",ROUND((N('Танин мэдэхүй'!F15)+N('Танин мэдэхүй'!H15)+N('Танин мэдэхүй'!J15)+N('Нийгэмшил'!D15)+N('Танин мэдэхүй'!L15)+N('Танин мэдэхүй'!N15)+N('Нийгэмшил'!F15)+N('Танин мэдэхүй'!X15)+N('Танин мэдэхүй'!Z15)+N('Танин мэдэхүй'!AB15)+N('Нийгэмшил'!J15)+N('Танин мэдэхүй'!AL15)+N('Танин мэдэхүй'!AN15)+N('Нийгэмшил'!N15))/14*100,1)) | M12: ='Бие бялдар'!V15+'Танин мэдэхүй'!AP15+'Нийгэмшил'!V15 | N12: =IF(('Бие бялдар'!V15+'Бие бялдар'!X15+'Танин мэдэхүй'!AP15+'Танин мэдэхүй'!AR15+'Нийгэмшил'!V15+'Нийгэмшил'!X15)=0,"",ROUND(M12/37*100,1)) | O12: =IF(N12="","",IF(N12>=80,"Хангалттай эзэмшиж байна",IF(N12>=50,"Ахиж байна","Хөгжиж байна")))
A13: 7 | C13: =IF(('Бие бялдар'!V16+'Бие бялдар'!X16+'Танин мэдэхүй'!AP16+'Танин мэдэхүй'!AR16+'Нийгэмшил'!V16+'Нийгэмшил'!X16)=0,"",ROUND(('Бие бялдар'!V16)/9*100,1)) | D13: =IF(('Бие бялдар'!V16+'Бие бялдар'!X16+'Танин мэдэхүй'!AP16+'Танин мэдэхүй'!AR16+'Нийгэмшил'!V16+'Нийгэмшил'!X16)=0,"",ROUND(('Танин мэдэхүй'!AP16)/19*100,1)) | E13: =IF(('Бие бялдар'!V16+'Бие бялдар'!X16+'Танин мэдэхүй'!AP16+'Танин мэдэхүй'!AR16+'Нийгэмшил'!V16+'Нийгэмшил'!X16)=0,"",ROUND(('Нийгэмшил'!V16)/9*100,1)) | F13: =IF(('Бие бялдар'!V16+'Бие бялдар'!X16+'Танин мэдэхүй'!AP16+'Танин мэдэхүй'!AR16+'Нийгэмшил'!V16+'Нийгэмшил'!X16)=0,"",ROUND((N('Бие бялдар'!D16)+N('Бие бялдар'!F16)+N('Танин мэдэхүй'!D16)+N('Танин мэдэхүй'!F16)+N('Танин мэдэхүй'!H16)+N('Танин мэдэхүй'!J16)+N('Нийгэмшил'!D16)+N('Танин мэдэхүй'!L16)+N('Танин мэдэхүй'!N16)+N('Нийгэмшил'!F16)+N('Нийгэмшил'!H16))/11*100,1)) | G13: =IF(('Бие бялдар'!V16+'Бие бялдар'!X16+'Танин мэдэхүй'!AP16+'Танин мэдэхүй'!AR16+'Нийгэмшил'!V16+'Нийгэмшил'!X16)=0,"",ROUND((N('Бие бялдар'!H16)+N('Бие бялдар'!J16)+N('Бие бялдар'!L16)+N('Бие бялдар'!N16)+N('Бие бялдар'!P16)+N('Бие бялдар'!R16)+N('Бие бялдар'!T16)+N('Танин мэдэхүй'!P16)+N('Танин мэдэхүй'!R16)+N('Танин мэдэхүй'!T16)+N('Танин мэдэхүй'!V16)+N('Танин мэдэхүй'!X16)+N('Танин мэдэхүй'!Z16)+N('Танин мэдэхүй'!AB16)+N('Танин мэдэхүй'!AD16)+N('Нийгэмшил'!J16)+N('Танин мэдэхүй'!AF16)+N('Танин мэдэхүй'!AH16)+N('Танин мэдэхүй'!AJ16)+N('Нийгэмшил'!L16)+N('Танин мэдэхүй'!AL16)+N('Танин мэдэхүй'!AN16))/22*100,1)) | H13: =IF(('Бие бялдар'!V16+'Бие бялдар'!X16+'Танин мэдэхүй'!AP16+'Танин мэдэхүй'!AR16+'Нийгэмшил'!V16+'Нийгэмшил'!X16)=0,"",ROUND((N('Нийгэмшил'!N16)+N('Нийгэмшил'!P16)+N('Нийгэмшил'!R16)+N('Нийгэмшил'!T16))/4*100,1)) | I13: =IF(('Бие бялдар'!V16+'Бие бялдар'!X16+'Танин мэдэхүй'!AP16+'Танин мэдэхүй'!AR16+'Нийгэмшил'!V16+'Нийгэмшил'!X16)=0,"",ROUND((N('Бие бялдар'!D16)+N('Бие бялдар'!F16)+N('Бие бялдар'!R16)+N('Бие бялдар'!T16)+N('Нийгэмшил'!P16)+N('Нийгэмшил'!R16)+N('Нийгэмшил'!T16))/7*100,1)) | J13: =IF(('Бие бялдар'!V16+'Бие бялдар'!X16+'Танин мэдэхүй'!AP16+'Танин мэдэхүй'!AR16+'Нийгэмшил'!V16+'Нийгэмшил'!X16)=0,"",ROUND((N('Бие бялдар'!H16)+N('Бие бялдар'!J16)+N('Бие бялдар'!L16)+N('Бие бялдар'!N16)+N('Бие бялдар'!P16)+N('Танин мэдэхүй'!AD16)+N('Танин мэдэхүй'!AF16)+N('Танин мэдэхүй'!AH16)+N('Танин мэдэхүй'!AJ16))/9*100,1)) | K13: =IF(('Бие бялдар'!V16+'Бие бялдар'!X16+'Танин мэдэхүй'!AP16+'Танин мэдэхүй'!AR16+'Нийгэмшил'!V16+'Нийгэмшил'!X16)=0,"",ROUND((N('Танин мэдэхүй'!D16)+N('Нийгэмшил'!H16)+N('Танин мэдэхүй'!P16)+N('Танин мэдэхүй'!R16)+N('Танин мэдэхүй'!T16)+N('Танин мэдэхүй'!V16)+N('Нийгэмшил'!L16))/7*100,1)) | L13: =IF(('Бие бялдар'!V16+'Бие бялдар'!X16+'Танин мэдэхүй'!AP16+'Танин мэдэхүй'!AR16+'Нийгэмшил'!V16+'Нийгэмшил'!X16)=0,"",ROUND((N('Танин мэдэхүй'!F16)+N('Танин мэдэхүй'!H16)+N('Танин мэдэхүй'!J16)+N('Нийгэмшил'!D16)+N('Танин мэдэхүй'!L16)+N('Танин мэдэхүй'!N16)+N('Нийгэмшил'!F16)+N('Танин мэдэхүй'!X16)+N('Танин мэдэхүй'!Z16)+N('Танин мэдэхүй'!AB16)+N('Нийгэмшил'!J16)+N('Танин мэдэхүй'!AL16)+N('Танин мэдэхүй'!AN16)+N('Нийгэмшил'!N16))/14*100,1)) | M13: ='Бие бялдар'!V16+'Танин мэдэхүй'!AP16+'Нийгэмшил'!V16 | N13: =IF(('Бие бялдар'!V16+'Бие бялдар'!X16+'Танин мэдэхүй'!AP16+'Танин мэдэхүй'!AR16+'Нийгэмшил'!V16+'Нийгэмшил'!X16)=0,"",ROUND(M13/37*100,1)) | O13: =IF(N13="","",IF(N13>=80,"Хангалттай эзэмшиж байна",IF(N13>=50,"Ахиж байна","Хөгжиж байна")))
A14: 8 | C14: =IF(('Бие бялдар'!V17+'Бие бялдар'!X17+'Танин мэдэхүй'!AP17+'Танин мэдэхүй'!AR17+'Нийгэмшил'!V17+'Нийгэмшил'!X17)=0,"",ROUND(('Бие бялдар'!V17)/9*100,1)) | D14: =IF(('Бие бялдар'!V17+'Бие бялдар'!X17+'Танин мэдэхүй'!AP17+'Танин мэдэхүй'!AR17+'Нийгэмшил'!V17+'Нийгэмшил'!X17)=0,"",ROUND(('Танин мэдэхүй'!AP17)/19*100,1)) | E14: =IF(('Бие бялдар'!V17+'Бие бялдар'!X17+'Танин мэдэхүй'!AP17+'Танин мэдэхүй'!AR17+'Нийгэмшил'!V17+'Нийгэмшил'!X17)=0,"",ROUND(('Нийгэмшил'!V17)/9*100,1)) | F14: =IF(('Бие бялдар'!V17+'Бие бялдар'!X17+'Танин мэдэхүй'!AP17+'Танин мэдэхүй'!AR17+'Нийгэмшил'!V17+'Нийгэмшил'!X17)=0,"",ROUND((N('Бие бялдар'!D17)+N('Бие бялдар'!F17)+N('Танин мэдэхүй'!D17)+N('Танин мэдэхүй'!F17)+N('Танин мэдэхүй'!H17)+N('Танин мэдэхүй'!J17)+N('Нийгэмшил'!D17)+N('Танин мэдэхүй'!L17)+N('Танин мэдэхүй'!N17)+N('Нийгэмшил'!F17)+N('Нийгэмшил'!H17))/11*100,1)) | G14: =IF(('Бие бялдар'!V17+'Бие бялдар'!X17+'Танин мэдэхүй'!AP17+'Танин мэдэхүй'!AR17+'Нийгэмшил'!V17+'Нийгэмшил'!X17)=0,"",ROUND((N('Бие бялдар'!H17)+N('Бие бялдар'!J17)+N('Бие бялдар'!L17)+N('Бие бялдар'!N17)+N('Бие бялдар'!P17)+N('Бие бялдар'!R17)+N('Бие бялдар'!T17)+N('Танин мэдэхүй'!P17)+N('Танин мэдэхүй'!R17)+N('Танин мэдэхүй'!T17)+N('Танин мэдэхүй'!V17)+N('Танин мэдэхүй'!X17)+N('Танин мэдэхүй'!Z17)+N('Танин мэдэхүй'!AB17)+N('Танин мэдэхүй'!AD17)+N('Нийгэмшил'!J17)+N('Танин мэдэхүй'!AF17)+N('Танин мэдэхүй'!AH17)+N('Танин мэдэхүй'!AJ17)+N('Нийгэмшил'!L17)+N('Танин мэдэхүй'!AL17)+N('Танин мэдэхүй'!AN17))/22*100,1)) | H14: =IF(('Бие бялдар'!V17+'Бие бялдар'!X17+'Танин мэдэхүй'!AP17+'Танин мэдэхүй'!AR17+'Нийгэмшил'!V17+'Нийгэмшил'!X17)=0,"",ROUND((N('Нийгэмшил'!N17)+N('Нийгэмшил'!P17)+N('Нийгэмшил'!R17)+N('Нийгэмшил'!T17))/4*100,1)) | I14: =IF(('Бие бялдар'!V17+'Бие бялдар'!X17+'Танин мэдэхүй'!AP17+'Танин мэдэхүй'!AR17+'Нийгэмшил'!V17+'Нийгэмшил'!X17)=0,"",ROUND((N('Бие бялдар'!D17)+N('Бие бялдар'!F17)+N('Бие бялдар'!R17)+N('Бие бялдар'!T17)+N('Нийгэмшил'!P17)+N('Нийгэмшил'!R17)+N('Нийгэмшил'!T17))/7*100,1)) | J14: =IF(('Бие бялдар'!V17+'Бие бялдар'!X17+'Танин мэдэхүй'!AP17+'Танин мэдэхүй'!AR17+'Нийгэмшил'!V17+'Нийгэмшил'!X17)=0,"",ROUND((N('Бие бялдар'!H17)+N('Бие бялдар'!J17)+N('Бие бялдар'!L17)+N('Бие бялдар'!N17)+N('Бие бялдар'!P17)+N('Танин мэдэхүй'!AD17)+N('Танин мэдэхүй'!AF17)+N('Танин мэдэхүй'!AH17)+N('Танин мэдэхүй'!AJ17))/9*100,1)) | K14: =IF(('Бие бялдар'!V17+'Бие бялдар'!X17+'Танин мэдэхүй'!AP17+'Танин мэдэхүй'!AR17+'Нийгэмшил'!V17+'Нийгэмшил'!X17)=0,"",ROUND((N('Танин мэдэхүй'!D17)+N('Нийгэмшил'!H17)+N('Танин мэдэхүй'!P17)+N('Танин мэдэхүй'!R17)+N('Танин мэдэхүй'!T17)+N('Танин мэдэхүй'!V17)+N('Нийгэмшил'!L17))/7*100,1)) | L14: =IF(('Бие бялдар'!V17+'Бие бялдар'!X17+'Танин мэдэхүй'!AP17+'Танин мэдэхүй'!AR17+'Нийгэмшил'!V17+'Нийгэмшил'!X17)=0,"",ROUND((N('Танин мэдэхүй'!F17)+N('Танин мэдэхүй'!H17)+N('Танин мэдэхүй'!J17)+N('Нийгэмшил'!D17)+N('Танин мэдэхүй'!L17)+N('Танин мэдэхүй'!N17)+N('Нийгэмшил'!F17)+N('Танин мэдэхүй'!X17)+N('Танин мэдэхүй'!Z17)+N('Танин мэдэхүй'!AB17)+N('Нийгэмшил'!J17)+N('Танин мэдэхүй'!AL17)+N('Танин мэдэхүй'!AN17)+N('Нийгэмшил'!N17))/14*100,1)) | M14: ='Бие бялдар'!V17+'Танин мэдэхүй'!AP17+'Нийгэмшил'!V17 | N14: =IF(('Бие бялдар'!V17+'Бие бялдар'!X17+'Танин мэдэхүй'!AP17+'Танин мэдэхүй'!AR17+'Нийгэмшил'!V17+'Нийгэмшил'!X17)=0,"",ROUND(M14/37*100,1)) | O14: =IF(N14="","",IF(N14>=80,"Хангалттай эзэмшиж байна",IF(N14>=50,"Ахиж байна","Хөгжиж байна")))
A15: 9 | C15: =IF(('Бие бялдар'!V18+'Бие бялдар'!X18+'Танин мэдэхүй'!AP18+'Танин мэдэхүй'!AR18+'Нийгэмшил'!V18+'Нийгэмшил'!X18)=0,"",ROUND(('Бие бялдар'!V18)/9*100,1)) | D15: =IF(('Бие бялдар'!V18+'Бие бялдар'!X18+'Танин мэдэхүй'!AP18+'Танин мэдэхүй'!AR18+'Нийгэмшил'!V18+'Нийгэмшил'!X18)=0,"",ROUND(('Танин мэдэхүй'!AP18)/19*100,1)) | E15: =IF(('Бие бялдар'!V18+'Бие бялдар'!X18+'Танин мэдэхүй'!AP18+'Танин мэдэхүй'!AR18+'Нийгэмшил'!V18+'Нийгэмшил'!X18)=0,"",ROUND(('Нийгэмшил'!V18)/9*100,1)) | F15: =IF(('Бие бялдар'!V18+'Бие бялдар'!X18+'Танин мэдэхүй'!AP18+'Танин мэдэхүй'!AR18+'Нийгэмшил'!V18+'Нийгэмшил'!X18)=0,"",ROUND((N('Бие бялдар'!D18)+N('Бие бялдар'!F18)+N('Танин мэдэхүй'!D18)+N('Танин мэдэхүй'!F18)+N('Танин мэдэхүй'!H18)+N('Танин мэдэхүй'!J18)+N('Нийгэмшил'!D18)+N('Танин мэдэхүй'!L18)+N('Танин мэдэхүй'!N18)+N('Нийгэмшил'!F18)+N('Нийгэмшил'!H18))/11*100,1)) | G15: =IF(('Бие бялдар'!V18+'Бие бялдар'!X18+'Танин мэдэхүй'!AP18+'Танин мэдэхүй'!AR18+'Нийгэмшил'!V18+'Нийгэмшил'!X18)=0,"",ROUND((N('Бие бялдар'!H18)+N('Бие бялдар'!J18)+N('Бие бялдар'!L18)+N('Бие бялдар'!N18)+N('Бие бялдар'!P18)+N('Бие бялдар'!R18)+N('Бие бялдар'!T18)+N('Танин мэдэхүй'!P18)+N('Танин мэдэхүй'!R18)+N('Танин мэдэхүй'!T18)+N('Танин мэдэхүй'!V18)+N('Танин мэдэхүй'!X18)+N('Танин мэдэхүй'!Z18)+N('Танин мэдэхүй'!AB18)+N('Танин мэдэхүй'!AD18)+N('Нийгэмшил'!J18)+N('Танин мэдэхүй'!AF18)+N('Танин мэдэхүй'!AH18)+N('Танин мэдэхүй'!AJ18)+N('Нийгэмшил'!L18)+N('Танин мэдэхүй'!AL18)+N('Танин мэдэхүй'!AN18))/22*100,1)) | H15: =IF(('Бие бялдар'!V18+'Бие бялдар'!X18+'Танин мэдэхүй'!AP18+'Танин мэдэхүй'!AR18+'Нийгэмшил'!V18+'Нийгэмшил'!X18)=0,"",ROUND((N('Нийгэмшил'!N18)+N('Нийгэмшил'!P18)+N('Нийгэмшил'!R18)+N('Нийгэмшил'!T18))/4*100,1)) | I15: =IF(('Бие бялдар'!V18+'Бие бялдар'!X18+'Танин мэдэхүй'!AP18+'Танин мэдэхүй'!AR18+'Нийгэмшил'!V18+'Нийгэмшил'!X18)=0,"",ROUND((N('Бие бялдар'!D18)+N('Бие бялдар'!F18)+N('Бие бялдар'!R18)+N('Бие бялдар'!T18)+N('Нийгэмшил'!P18)+N('Нийгэмшил'!R18)+N('Нийгэмшил'!T18))/7*100,1)) | J15: =IF(('Бие бялдар'!V18+'Бие бялдар'!X18+'Танин мэдэхүй'!AP18+'Танин мэдэхүй'!AR18+'Нийгэмшил'!V18+'Нийгэмшил'!X18)=0,"",ROUND((N('Бие бялдар'!H18)+N('Бие бялдар'!J18)+N('Бие бялдар'!L18)+N('Бие бялдар'!N18)+N('Бие бялдар'!P18)+N('Танин мэдэхүй'!AD18)+N('Танин мэдэхүй'!AF18)+N('Танин мэдэхүй'!AH18)+N('Танин мэдэхүй'!AJ18))/9*100,1)) | K15: =IF(('Бие бялдар'!V18+'Бие бялдар'!X18+'Танин мэдэхүй'!AP18+'Танин мэдэхүй'!AR18+'Нийгэмшил'!V18+'Нийгэмшил'!X18)=0,"",ROUND((N('Танин мэдэхүй'!D18)+N('Нийгэмшил'!H18)+N('Танин мэдэхүй'!P18)+N('Танин мэдэхүй'!R18)+N('Танин мэдэхүй'!T18)+N('Танин мэдэхүй'!V18)+N('Нийгэмшил'!L18))/7*100,1)) | L15: =IF(('Бие бялдар'!V18+'Бие бялдар'!X18+'Танин мэдэхүй'!AP18+'Танин мэдэхүй'!AR18+'Нийгэмшил'!V18+'Нийгэмшил'!X18)=0,"",ROUND((N('Танин мэдэхүй'!F18)+N('Танин мэдэхүй'!H18)+N('Танин мэдэхүй'!J18)+N('Нийгэмшил'!D18)+N('Танин мэдэхүй'!L18)+N('Танин мэдэхүй'!N18)+N('Нийгэмшил'!F18)+N('Танин мэдэхүй'!X18)+N('Танин мэдэхүй'!Z18)+N('Танин мэдэхүй'!AB18)+N('Нийгэмшил'!J18)+N('Танин мэдэхүй'!AL18)+N('Танин мэдэхүй'!AN18)+N('Нийгэмшил'!N18))/14*100,1)) | M15: ='Бие бялдар'!V18+'Танин мэдэхүй'!AP18+'Нийгэмшил'!V18 | N15: =IF(('Бие бялдар'!V18+'Бие бялдар'!X18+'Танин мэдэхүй'!AP18+'Танин мэдэхүй'!AR18+'Нийгэмшил'!V18+'Нийгэмшил'!X18)=0,"",ROUND(M15/37*100,1)) | O15: =IF(N15="","",IF(N15>=80,"Хангалттай эзэмшиж байна",IF(N15>=50,"Ахиж байна","Хөгжиж байна")))
A16: 10 | C16: =IF(('Бие бялдар'!V19+'Бие бялдар'!X19+'Танин мэдэхүй'!AP19+'Танин мэдэхүй'!AR19+'Нийгэмшил'!V19+'Нийгэмшил'!X19)=0,"",ROUND(('Бие бялдар'!V19)/9*100,1)) | D16: =IF(('Бие бялдар'!V19+'Бие бялдар'!X19+'Танин мэдэхүй'!AP19+'Танин мэдэхүй'!AR19+'Нийгэмшил'!V19+'Нийгэмшил'!X19)=0,"",ROUND(('Танин мэдэхүй'!AP19)/19*100,1)) | E16: =IF(('Бие бялдар'!V19+'Бие бялдар'!X19+'Танин мэдэхүй'!AP19+'Танин мэдэхүй'!AR19+'Нийгэмшил'!V19+'Нийгэмшил'!X19)=0,"",ROUND(('Нийгэмшил'!V19)/9*100,1)) | F16: =IF(('Бие бялдар'!V19+'Бие бялдар'!X19+'Танин мэдэхүй'!AP19+'Танин мэдэхүй'!AR19+'Нийгэмшил'!V19+'Нийгэмшил'!X19)=0,"",ROUND((N('Бие бялдар'!D19)+N('Бие бялдар'!F19)+N('Танин мэдэхүй'!D19)+N('Танин мэдэхүй'!F19)+N('Танин мэдэхүй'!H19)+N('Танин мэдэхүй'!J19)+N('Нийгэмшил'!D19)+N('Танин мэдэхүй'!L19)+N('Танин мэдэхүй'!N19)+N('Нийгэмшил'!F19)+N('Нийгэмшил'!H19))/11*100,1)) | G16: =IF(('Бие бялдар'!V19+'Бие бялдар'!X19+'Танин мэдэхүй'!AP19+'Танин мэдэхүй'!AR19+'Нийгэмшил'!V19+'Нийгэмшил'!X19)=0,"",ROUND((N('Бие бялдар'!H19)+N('Бие бялдар'!J19)+N('Бие бялдар'!L19)+N('Бие бялдар'!N19)+N('Бие бялдар'!P19)+N('Бие бялдар'!R19)+N('Бие бялдар'!T19)+N('Танин мэдэхүй'!P19)+N('Танин мэдэхүй'!R19)+N('Танин мэдэхүй'!T19)+N('Танин мэдэхүй'!V19)+N('Танин мэдэхүй'!X19)+N('Танин мэдэхүй'!Z19)+N('Танин мэдэхүй'!AB19)+N('Танин мэдэхүй'!AD19)+N('Нийгэмшил'!J19)+N('Танин мэдэхүй'!AF19)+N('Танин мэдэхүй'!AH19)+N('Танин мэдэхүй'!AJ19)+N('Нийгэмшил'!L19)+N('Танин мэдэхүй'!AL19)+N('Танин мэдэхүй'!AN19))/22*100,1)) | H16: =IF(('Бие бялдар'!V19+'Бие бялдар'!X19+'Танин мэдэхүй'!AP19+'Танин мэдэхүй'!AR19+'Нийгэмшил'!V19+'Нийгэмшил'!X19)=0,"",ROUND((N('Нийгэмшил'!N19)+N('Нийгэмшил'!P19)+N('Нийгэмшил'!R19)+N('Нийгэмшил'!T19))/4*100,1)) | I16: =IF(('Бие бялдар'!V19+'Бие бялдар'!X19+'Танин мэдэхүй'!AP19+'Танин мэдэхүй'!AR19+'Нийгэмшил'!V19+'Нийгэмшил'!X19)=0,"",ROUND((N('Бие бялдар'!D19)+N('Бие бялдар'!F19)+N('Бие бялдар'!R19)+N('Бие бялдар'!T19)+N('Нийгэмшил'!P19)+N('Нийгэмшил'!R19)+N('Нийгэмшил'!T19))/7*100,1)) | J16: =IF(('Бие бялдар'!V19+'Бие бялдар'!X19+'Танин мэдэхүй'!AP19+'Танин мэдэхүй'!AR19+'Нийгэмшил'!V19+'Нийгэмшил'!X19)=0,"",ROUND((N('Бие бялдар'!H19)+N('Бие бялдар'!J19)+N('Бие бялдар'!L19)+N('Бие бялдар'!N19)+N('Бие бялдар'!P19)+N('Танин мэдэхүй'!AD19)+N('Танин мэдэхүй'!AF19)+N('Танин мэдэхүй'!AH19)+N('Танин мэдэхүй'!AJ19))/9*100,1)) | K16: =IF(('Бие бялдар'!V19+'Бие бялдар'!X19+'Танин мэдэхүй'!AP19+'Танин мэдэхүй'!AR19+'Нийгэмшил'!V19+'Нийгэмшил'!X19)=0,"",ROUND((N('Танин мэдэхүй'!D19)+N('Нийгэмшил'!H19)+N('Танин мэдэхүй'!P19)+N('Танин мэдэхүй'!R19)+N('Танин мэдэхүй'!T19)+N('Танин мэдэхүй'!V19)+N('Нийгэмшил'!L19))/7*100,1)) | L16: =IF(('Бие бялдар'!V19+'Бие бялдар'!X19+'Танин мэдэхүй'!AP19+'Танин мэдэхүй'!AR19+'Нийгэмшил'!V19+'Нийгэмшил'!X19)=0,"",ROUND((N('Танин мэдэхүй'!F19)+N('Танин мэдэхүй'!H19)+N('Танин мэдэхүй'!J19)+N('Нийгэмшил'!D19)+N('Танин мэдэхүй'!L19)+N('Танин мэдэхүй'!N19)+N('Нийгэмшил'!F19)+N('Танин мэдэхүй'!X19)+N('Танин мэдэхүй'!Z19)+N('Танин мэдэхүй'!AB19)+N('Нийгэмшил'!J19)+N('Танин мэдэхүй'!AL19)+N('Танин мэдэхүй'!AN19)+N('Нийгэмшил'!N19))/14*100,1)) | M16: ='Бие бялдар'!V19+'Танин мэдэхүй'!AP19+'Нийгэмшил'!V19 | N16: =IF(('Бие бялдар'!V19+'Бие бялдар'!X19+'Танин мэдэхүй'!AP19+'Танин мэдэхүй'!AR19+'Нийгэмшил'!V19+'Нийгэмшил'!X19)=0,"",ROUND(M16/37*100,1)) | O16: =IF(N16="","",IF(N16>=80,"Хангалттай эзэмшиж байна",IF(N16>=50,"Ахиж байна","Хөгжиж байна")))
A17: 11 | C17: =IF(('Бие бялдар'!V20+'Бие бялдар'!X20+'Танин мэдэхүй'!AP20+'Танин мэдэхүй'!AR20+'Нийгэмшил'!V20+'Нийгэмшил'!X20)=0,"",ROUND(('Бие бялдар'!V20)/9*100,1)) | D17: =IF(('Бие бялдар'!V20+'Бие бялдар'!X20+'Танин мэдэхүй'!AP20+'Танин мэдэхүй'!AR20+'Нийгэмшил'!V20+'Нийгэмшил'!X20)=0,"",ROUND(('Танин мэдэхүй'!AP20)/19*100,1)) | E17: =IF(('Бие бялдар'!V20+'Бие бялдар'!X20+'Танин мэдэхүй'!AP20+'Танин мэдэхүй'!AR20+'Нийгэмшил'!V20+'Нийгэмшил'!X20)=0,"",ROUND(('Нийгэмшил'!V20)/9*100,1)) | F17: =IF(('Бие бялдар'!V20+'Бие бялдар'!X20+'Танин мэдэхүй'!AP20+'Танин мэдэхүй'!AR20+'Нийгэмшил'!V20+'Нийгэмшил'!X20)=0,"",ROUND((N('Бие бялдар'!D20)+N('Бие бялдар'!F20)+N('Танин мэдэхүй'!D20)+N('Танин мэдэхүй'!F20)+N('Танин мэдэхүй'!H20)+N('Танин мэдэхүй'!J20)+N('Нийгэмшил'!D20)+N('Танин мэдэхүй'!L20)+N('Танин мэдэхүй'!N20)+N('Нийгэмшил'!F20)+N('Нийгэмшил'!H20))/11*100,1)) | G17: =IF(('Бие бялдар'!V20+'Бие бялдар'!X20+'Танин мэдэхүй'!AP20+'Танин мэдэхүй'!AR20+'Нийгэмшил'!V20+'Нийгэмшил'!X20)=0,"",ROUND((N('Бие бялдар'!H20)+N('Бие бялдар'!J20)+N('Бие бялдар'!L20)+N('Бие бялдар'!N20)+N('Бие бялдар'!P20)+N('Бие бялдар'!R20)+N('Бие бялдар'!T20)+N('Танин мэдэхүй'!P20)+N('Танин мэдэхүй'!R20)+N('Танин мэдэхүй'!T20)+N('Танин мэдэхүй'!V20)+N('Танин мэдэхүй'!X20)+N('Танин мэдэхүй'!Z20)+N('Танин мэдэхүй'!AB20)+N('Танин мэдэхүй'!AD20)+N('Нийгэмшил'!J20)+N('Танин мэдэхүй'!AF20)+N('Танин мэдэхүй'!AH20)+N('Танин мэдэхүй'!AJ20)+N('Нийгэмшил'!L20)+N('Танин мэдэхүй'!AL20)+N('Танин мэдэхүй'!AN20))/22*100,1)) | H17: =IF(('Бие бялдар'!V20+'Бие бялдар'!X20+'Танин мэдэхүй'!AP20+'Танин мэдэхүй'!AR20+'Нийгэмшил'!V20+'Нийгэмшил'!X20)=0,"",ROUND((N('Нийгэмшил'!N20)+N('Нийгэмшил'!P20)+N('Нийгэмшил'!R20)+N('Нийгэмшил'!T20))/4*100,1)) | I17: =IF(('Бие бялдар'!V20+'Бие бялдар'!X20+'Танин мэдэхүй'!AP20+'Танин мэдэхүй'!AR20+'Нийгэмшил'!V20+'Нийгэмшил'!X20)=0,"",ROUND((N('Бие бялдар'!D20)+N('Бие бялдар'!F20)+N('Бие бялдар'!R20)+N('Бие бялдар'!T20)+N('Нийгэмшил'!P20)+N('Нийгэмшил'!R20)+N('Нийгэмшил'!T20))/7*100,1)) | J17: =IF(('Бие бялдар'!V20+'Бие бялдар'!X20+'Танин мэдэхүй'!AP20+'Танин мэдэхүй'!AR20+'Нийгэмшил'!V20+'Нийгэмшил'!X20)=0,"",ROUND((N('Бие бялдар'!H20)+N('Бие бялдар'!J20)+N('Бие бялдар'!L20)+N('Бие бялдар'!N20)+N('Бие бялдар'!P20)+N('Танин мэдэхүй'!AD20)+N('Танин мэдэхүй'!AF20)+N('Танин мэдэхүй'!AH20)+N('Танин мэдэхүй'!AJ20))/9*100,1)) | K17: =IF(('Бие бялдар'!V20+'Бие бялдар'!X20+'Танин мэдэхүй'!AP20+'Танин мэдэхүй'!AR20+'Нийгэмшил'!V20+'Нийгэмшил'!X20)=0,"",ROUND((N('Танин мэдэхүй'!D20)+N('Нийгэмшил'!H20)+N('Танин мэдэхүй'!P20)+N('Танин мэдэхүй'!R20)+N('Танин мэдэхүй'!T20)+N('Танин мэдэхүй'!V20)+N('Нийгэмшил'!L20))/7*100,1)) | L17: =IF(('Бие бялдар'!V20+'Бие бялдар'!X20+'Танин мэдэхүй'!AP20+'Танин мэдэхүй'!AR20+'Нийгэмшил'!V20+'Нийгэмшил'!X20)=0,"",ROUND((N('Танин мэдэхүй'!F20)+N('Танин мэдэхүй'!H20)+N('Танин мэдэхүй'!J20)+N('Нийгэмшил'!D20)+N('Танин мэдэхүй'!L20)+N('Танин мэдэхүй'!N20)+N('Нийгэмшил'!F20)+N('Танин мэдэхүй'!X20)+N('Танин мэдэхүй'!Z20)+N('Танин мэдэхүй'!AB20)+N('Нийгэмшил'!J20)+N('Танин мэдэхүй'!AL20)+N('Танин мэдэхүй'!AN20)+N('Нийгэмшил'!N20))/14*100,1)) | M17: ='Бие бялдар'!V20+'Танин мэдэхүй'!AP20+'Нийгэмшил'!V20 | N17: =IF(('Бие бялдар'!V20+'Бие бялдар'!X20+'Танин мэдэхүй'!AP20+'Танин мэдэхүй'!AR20+'Нийгэмшил'!V20+'Нийгэмшил'!X20)=0,"",ROUND(M17/37*100,1)) | O17: =IF(N17="","",IF(N17>=80,"Хангалттай эзэмшиж байна",IF(N17>=50,"Ахиж байна","Хөгжиж байна")))
A18: 12 | C18: =IF(('Бие бялдар'!V21+'Бие бялдар'!X21+'Танин мэдэхүй'!AP21+'Танин мэдэхүй'!AR21+'Нийгэмшил'!V21+'Нийгэмшил'!X21)=0,"",ROUND(('Бие бялдар'!V21)/9*100,1)) | D18: =IF(('Бие бялдар'!V21+'Бие бялдар'!X21+'Танин мэдэхүй'!AP21+'Танин мэдэхүй'!AR21+'Нийгэмшил'!V21+'Нийгэмшил'!X21)=0,"",ROUND(('Танин мэдэхүй'!AP21)/19*100,1)) | E18: =IF(('Бие бялдар'!V21+'Бие бялдар'!X21+'Танин мэдэхүй'!AP21+'Танин мэдэхүй'!AR21+'Нийгэмшил'!V21+'Нийгэмшил'!X21)=0,"",ROUND(('Нийгэмшил'!V21)/9*100,1)) | F18: =IF(('Бие бялдар'!V21+'Бие бялдар'!X21+'Танин мэдэхүй'!AP21+'Танин мэдэхүй'!AR21+'Нийгэмшил'!V21+'Нийгэмшил'!X21)=0,"",ROUND((N('Бие бялдар'!D21)+N('Бие бялдар'!F21)+N('Танин мэдэхүй'!D21)+N('Танин мэдэхүй'!F21)+N('Танин мэдэхүй'!H21)+N('Танин мэдэхүй'!J21)+N('Нийгэмшил'!D21)+N('Танин мэдэхүй'!L21)+N('Танин мэдэхүй'!N21)+N('Нийгэмшил'!F21)+N('Нийгэмшил'!H21))/11*100,1)) | G18: =IF(('Бие бялдар'!V21+'Бие бялдар'!X21+'Танин мэдэхүй'!AP21+'Танин мэдэхүй'!AR21+'Нийгэмшил'!V21+'Нийгэмшил'!X21)=0,"",ROUND((N('Бие бялдар'!H21)+N('Бие бялдар'!J21)+N('Бие бялдар'!L21)+N('Бие бялдар'!N21)+N('Бие бялдар'!P21)+N('Бие бялдар'!R21)+N('Бие бялдар'!T21)+N('Танин мэдэхүй'!P21)+N('Танин мэдэхүй'!R21)+N('Танин мэдэхүй'!T21)+N('Танин мэдэхүй'!V21)+N('Танин мэдэхүй'!X21)+N('Танин мэдэхүй'!Z21)+N('Танин мэдэхүй'!AB21)+N('Танин мэдэхүй'!AD21)+N('Нийгэмшил'!J21)+N('Танин мэдэхүй'!AF21)+N('Танин мэдэхүй'!AH21)+N('Танин мэдэхүй'!AJ21)+N('Нийгэмшил'!L21)+N('Танин мэдэхүй'!AL21)+N('Танин мэдэхүй'!AN21))/22*100,1)) | H18: =IF(('Бие бялдар'!V21+'Бие бялдар'!X21+'Танин мэдэхүй'!AP21+'Танин мэдэхүй'!AR21+'Нийгэмшил'!V21+'Нийгэмшил'!X21)=0,"",ROUND((N('Нийгэмшил'!N21)+N('Нийгэмшил'!P21)+N('Нийгэмшил'!R21)+N('Нийгэмшил'!T21))/4*100,1)) | I18: =IF(('Бие бялдар'!V21+'Бие бялдар'!X21+'Танин мэдэхүй'!AP21+'Танин мэдэхүй'!AR21+'Нийгэмшил'!V21+'Нийгэмшил'!X21)=0,"",ROUND((N('Бие бялдар'!D21)+N('Бие бялдар'!F21)+N('Бие бялдар'!R21)+N('Бие бялдар'!T21)+N('Нийгэмшил'!P21)+N('Нийгэмшил'!R21)+N('Нийгэмшил'!T21))/7*100,1)) | J18: =IF(('Бие бялдар'!V21+'Бие бялдар'!X21+'Танин мэдэхүй'!AP21+'Танин мэдэхүй'!AR21+'Нийгэмшил'!V21+'Нийгэмшил'!X21)=0,"",ROUND((N('Бие бялдар'!H21)+N('Бие бялдар'!J21)+N('Бие бялдар'!L21)+N('Бие бялдар'!N21)+N('Бие бялдар'!P21)+N('Танин мэдэхүй'!AD21)+N('Танин мэдэхүй'!AF21)+N('Танин мэдэхүй'!AH21)+N('Танин мэдэхүй'!AJ21))/9*100,1)) | K18: =IF(('Бие бялдар'!V21+'Бие бялдар'!X21+'Танин мэдэхүй'!AP21+'Танин мэдэхүй'!AR21+'Нийгэмшил'!V21+'Нийгэмшил'!X21)=0,"",ROUND((N('Танин мэдэхүй'!D21)+N('Нийгэмшил'!H21)+N('Танин мэдэхүй'!P21)+N('Танин мэдэхүй'!R21)+N('Танин мэдэхүй'!T21)+N('Танин мэдэхүй'!V21)+N('Нийгэмшил'!L21))/7*100,1)) | L18: =IF(('Бие бялдар'!V21+'Бие бялдар'!X21+'Танин мэдэхүй'!AP21+'Танин мэдэхүй'!AR21+'Нийгэмшил'!V21+'Нийгэмшил'!X21)=0,"",ROUND((N('Танин мэдэхүй'!F21)+N('Танин мэдэхүй'!H21)+N('Танин мэдэхүй'!J21)+N('Нийгэмшил'!D21)+N('Танин мэдэхүй'!L21)+N('Танин мэдэхүй'!N21)+N('Нийгэмшил'!F21)+N('Танин мэдэхүй'!X21)+N('Танин мэдэхүй'!Z21)+N('Танин мэдэхүй'!AB21)+N('Нийгэмшил'!J21)+N('Танин мэдэхүй'!AL21)+N('Танин мэдэхүй'!AN21)+N('Нийгэмшил'!N21))/14*100,1)) | M18: ='Бие бялдар'!V21+'Танин мэдэхүй'!AP21+'Нийгэмшил'!V21 | N18: =IF(('Бие бялдар'!V21+'Бие бялдар'!X21+'Танин мэдэхүй'!AP21+'Танин мэдэхүй'!AR21+'Нийгэмшил'!V21+'Нийгэмшил'!X21)=0,"",ROUND(M18/37*100,1)) | O18: =IF(N18="","",IF(N18>=80,"Хангалттай эзэмшиж байна",IF(N18>=50,"Ахиж байна","Хөгжиж байна")))
... A36: 30 | C36: =IF(('Бие бялдар'!V39+'Бие бялдар'!X39+'Танин мэдэхүй'!AP39+'Танин мэдэхүй'!AR39+'Нийгэмшил'!V39+'Нийгэмшил'!X39)=0,"",ROUND(('Бие бялдар'!V39)/9*100,1)) | D36: =IF(('Бие бялдар'!V39+'Бие бялдар'!X39+'Танин мэдэхүй'!AP39+'Танин мэдэхүй'!AR39+'Нийгэмшил'!V39+'Нийгэмшил'!X39)=0,"",ROUND(('Танин мэдэхүй'!AP39)/19*100,1)) | E36: =IF(('Бие бялдар'!V39+'Бие бялдар'!X39+'Танин мэдэхүй'!AP39+'Танин мэдэхүй'!AR39+'Нийгэмшил'!V39+'Нийгэмшил'!X39)=0,"",ROUND(('Нийгэмшил'!V39)/9*100,1)) | F36: =IF(('Бие бялдар'!V39+'Бие бялдар'!X39+'Танин мэдэхүй'!AP39+'Танин мэдэхүй'!AR39+'Нийгэмшил'!V39+'Нийгэмшил'!X39)=0,"",ROUND((N('Бие бялдар'!D39)+N('Бие бялдар'!F39)+N('Танин мэдэхүй'!D39)+N('Танин мэдэхүй'!F39)+N('Танин мэдэхүй'!H39)+N('Танин мэдэхүй'!J39)+N('Нийгэмшил'!D39)+N('Танин мэдэхүй'!L39)+N('Танин мэдэхүй'!N39)+N('Нийгэмшил'!F39)+N('Нийгэмшил'!H39))/11*100,1)) | G36: =IF(('Бие бялдар'!V39+'Бие бялдар'!X39+'Танин мэдэхүй'!AP39+'Танин мэдэхүй'!AR39+'Нийгэмшил'!V39+'Нийгэмшил'!X39)=0,"",ROUND((N('Бие бялдар'!H39)+N('Бие бялдар'!J39)+N('Бие бялдар'!L39)+N('Бие бялдар'!N39)+N('Бие бялдар'!P39)+N('Бие бялдар'!R39)+N('Бие бялдар'!T39)+N('Танин мэдэхүй'!P39)+N('Танин мэдэхүй'!R39)+N('Танин мэдэхүй'!T39)+N('Танин мэдэхүй'!V39)+N('Танин мэдэхүй'!X39)+N('Танин мэдэхүй'!Z39)+N('Танин мэдэхүй'!AB39)+N('Танин мэдэхүй'!AD39)+N('Нийгэмшил'!J39)+N('Танин мэдэхүй'!AF39)+N('Танин мэдэхүй'!AH39)+N('Танин мэдэхүй'!AJ39)+N('Нийгэмшил'!L39)+N('Танин мэдэхүй'!AL39)+N('Танин мэдэхүй'!AN39))/22*100,1)) | H36: =IF(('Бие бялдар'!V39+'Бие бялдар'!X39+'Танин мэдэхүй'!AP39+'Танин мэдэхүй'!AR39+'Нийгэмшил'!V39+'Нийгэмшил'!X39)=0,"",ROUND((N('Нийгэмшил'!N39)+N('Нийгэмшил'!P39)+N('Нийгэмшил'!R39)+N('Нийгэмшил'!T39))/4*100,1)) | I36: =IF(('Бие бялдар'!V39+'Бие бялдар'!X39+'Танин мэдэхүй'!AP39+'Танин мэдэхүй'!AR39+'Нийгэмшил'!V39+'Нийгэмшил'!X39)=0,"",ROUND((N('Бие бялдар'!D39)+N('Бие бялдар'!F39)+N('Бие бялдар'!R39)+N('Бие бялдар'!T39)+N('Нийгэмшил'!P39)+N('Нийгэмшил'!R39)+N('Нийгэмшил'!T39))/7*100,1)) | J36: =IF(('Бие бялдар'!V39+'Бие бялдар'!X39+'Танин мэдэхүй'!AP39+'Танин мэдэхүй'!AR39+'Нийгэмшил'!V39+'Нийгэмшил'!X39)=0,"",ROUND((N('Бие бялдар'!H39)+N('Бие бялдар'!J39)+N('Бие бялдар'!L39)+N('Бие бялдар'!N39)+N('Бие бялдар'!P39)+N('Танин мэдэхүй'!AD39)+N('Танин мэдэхүй'!AF39)+N('Танин мэдэхүй'!AH39)+N('Танин мэдэхүй'!AJ39))/9*100,1)) | K36: =IF(('Бие бялдар'!V39+'Бие бялдар'!X39+'Танин мэдэхүй'!AP39+'Танин мэдэхүй'!AR39+'Нийгэмшил'!V39+'Нийгэмшил'!X39)=0,"",ROUND((N('Танин мэдэхүй'!D39)+N('Нийгэмшил'!H39)+N('Танин мэдэхүй'!P39)+N('Танин мэдэхүй'!R39)+N('Танин мэдэхүй'!T39)+N('Танин мэдэхүй'!V39)+N('Нийгэмшил'!L39))/7*100,1)) | L36: =IF(('Бие бялдар'!V39+'Бие бялдар'!X39+'Танин мэдэхүй'!AP39+'Танин мэдэхүй'!AR39+'Нийгэмшил'!V39+'Нийгэмшил'!X39)=0,"",ROUND((N('Танин мэдэхүй'!F39)+N('Танин мэдэхүй'!H39)+N('Танин мэдэхүй'!J39)+N('Нийгэмшил'!D39)+N('Танин мэдэхүй'!L39)+N('Танин мэдэхүй'!N39)+N('Нийгэмшил'!F39)+N('Танин мэдэхүй'!X39)+N('Танин мэдэхүй'!Z39)+N('Танин мэдэхүй'!AB39)+N('Нийгэмшил'!J39)+N('Танин мэдэхүй'!AL39)+N('Танин мэдэхүй'!AN39)+N('Нийгэмшил'!N39))/14*100,1)) | M36: ='Бие бялдар'!V39+'Танин мэдэхүй'!AP39+'Нийгэмшил'!V39 | N36: =IF(('Бие бялдар'!V39+'Бие бялдар'!X39+'Танин мэдэхүй'!AP39+'Танин мэдэхүй'!AR39+'Нийгэмшил'!V39+'Нийгэмшил'!X39)=0,"",ROUND(M36/37*100,1)) | O36: =IF(N36="","",IF(N36>=80,"Хангалттай эзэмшиж байна",IF(N36>=50,"Ахиж байна","Хөгжиж байна")))
A37: Бүлгийн дундаж хувь | C37: =IFERROR(ROUND(AVERAGE(C7:C36),1),"") | D37: =IFERROR(ROUND(AVERAGE(D7:D36),1),"") | E37: =IFERROR(ROUND(AVERAGE(E7:E36),1),"") | F37: =IFERROR(ROUND(AVERAGE(F7:F36),1),"") | G37: =IFERROR(ROUND(AVERAGE(G7:G36),1),"") | H37: =IFERROR(ROUND(AVERAGE(H7:H36),1),"") | I37: =IFERROR(ROUND(AVERAGE(I7:I36),1),"") | J37: =IFERROR(ROUND(AVERAGE(J7:J36),1),"") | ... L37: =IFERROR(ROUND(AVERAGE(L7:L36),1),"") | N37: =IFERROR(ROUND(AVERAGE(N7:N36),1),"")
A38: Хангалттай эзэмшиж байна (хүүхдийн тоо) | C38: =COUNTIFS(C7:C36,">=80",C7:C36,"<=1000") | D38: =COUNTIFS(D7:D36,">=80",D7:D36,"<=1000") | E38: =COUNTIFS(E7:E36,">=80",E7:E36,"<=1000") | F38: =COUNTIFS(F7:F36,">=80",F7:F36,"<=1000") | G38: =COUNTIFS(G7:G36,">=80",G7:G36,"<=1000") | H38: =COUNTIFS(H7:H36,">=80",H7:H36,"<=1000") | I38: =COUNTIFS(I7:I36,">=80",I7:I36,"<=1000") | J38: =COUNTIFS(J7:J36,">=80",J7:J36,"<=1000") | ... L38: =COUNTIFS(L7:L36,">=80",L7:L36,"<=1000") | N38: =COUNTIFS(N7:N36,">=80",N7:N36,"<=1000") | O38: =COUNTIF(O7:O36,"Хангалттай эзэмшиж байна")
A39: Ахиж байна (хүүхдийн тоо) | C39: =COUNTIFS(C7:C36,">=50",C7:C36,"<=79.99") | D39: =COUNTIFS(D7:D36,">=50",D7:D36,"<=79.99") | E39: =COUNTIFS(E7:E36,">=50",E7:E36,"<=79.99") | F39: =COUNTIFS(F7:F36,">=50",F7:F36,"<=79.99") | G39: =COUNTIFS(G7:G36,">=50",G7:G36,"<=79.99") | H39: =COUNTIFS(H7:H36,">=50",H7:H36,"<=79.99") | I39: =COUNTIFS(I7:I36,">=50",I7:I36,"<=79.99") | J39: =COUNTIFS(J7:J36,">=50",J7:J36,"<=79.99") | ... L39: =COUNTIFS(L7:L36,">=50",L7:L36,"<=79.99") | N39: =COUNTIFS(N7:N36,">=50",N7:N36,"<=79.99") | O39: =COUNTIF(O7:O36,"Ахиж байна")
A40: Хөгжиж байна (хүүхдийн тоо) | C40: =COUNTIFS(C7:C36,">=0",C7:C36,"<=49.99") | D40: =COUNTIFS(D7:D36,">=0",D7:D36,"<=49.99") | E40: =COUNTIFS(E7:E36,">=0",E7:E36,"<=49.99") | F40: =COUNTIFS(F7:F36,">=0",F7:F36,"<=49.99") | G40: =COUNTIFS(G7:G36,">=0",G7:G36,"<=49.99") | H40: =COUNTIFS(H7:H36,">=0",H7:H36,"<=49.99") | I40: =COUNTIFS(I7:I36,">=0",I7:I36,"<=49.99") | J40: =COUNTIFS(J7:J36,">=0",J7:J36,"<=49.99") | ... L40: =COUNTIFS(L7:L36,">=0",L7:L36,"<=49.99") | N40: =COUNTIFS(N7:N36,">=0",N7:N36,"<=49.99") | O40: =COUNTIF(O7:O36,"Хөгжиж байна")

Sheet Бие бялдар
A1: ................ ЦЭЦЭРЛЭГИЙН БАГА БҮЛГИЙН (2 НАС) ГАРААНЫ (ОНОШЛОХ) ҮНЭЛГЭЭ
A2: Хөгжлийн чиглэл: Бие бялдар Огноо: 20.... оны .... сар Багш: ................................ (А/79 журам, I түвшний шалгуур)
A3: № | B3: Хүүхдийн нэр | D3: Хөгжлийн чиглэл: Бие бялдар | V3: Чадна | W3: Хувь | X3: Чадахгүй | Y3: Хувь | Z3: Түвшин
D4: [Мэдлэг · 10.5: Эрүүл мэнд] 1. Чанаж болгоогүй хүнсийг идэж болохгүйг мэддэг. | F4: [Мэдлэг · 10.5: Эрүүл мэнд] 2. Хүрээлэн байгаа орчноос болгоомжлох зүйлсийг таньдаг. | H4: [Чадвар · 10.5: Өсөлт] 12. 1-2 саадыг сүлжиж алхдаг (10 метр зайд). | J4: [Чадвар · 10.5: Өсөлт] 13. Хоорондоо 20 см зайтай байрлуулсан зураасны дундуур шулуун чиглэлээр гүйдэг. | L4: [Чадвар · 10.5: Өсөлт] 14. 20 см зайтай зураасны хооронд дөрвөн хөллөж мөлхдөг. | N4: [Чадвар · 10.5: Өсөлт] 15. Хоёр хөл дээрээ үсэрч буудаг. | P4: [Чадвар · 10.5: Өсөлт] 16. Тоглоом, юмс (бөмбөг, базсан цаас гэх мэт)-ыг тодорхой чиглэлд (урагш, дээш гэх мэт) шидэж дамжуулдаг. | R4: [Чадвар · 10.5: Эрүүл мэнд] 17. Гар, нүүр, шүдээ угаах, хоолой амаа зайлах үйлийг бусдын дэмжлэгтэйгээр хийж чаддаг. | T4: [Чадвар · 10.5: Эрүүл мэнд] 18. Хоолны хэрэгслийг зориулалтын дагуу хэрэглэдэг.
D5: СҮД: ХЭМ1.2в. Хоол хүнсний бүтээгдэхүүнийг угааж, чанаж болгож иддэгийг мэднэ, ялгана. | F5: СҮД: ХЭМ1.2е. Хүрээлэн буй орчинд байгаа болгоомжлох зүйлсийг мэднэ, ялгана. | H5: СҮД: ХЭМ1.1г. Байрандаа болон чиглэлээ өөрчилж алхаж, гүйнэ. | J5: СҮД: ХЭМ1.1г. Байрандаа болон чиглэлээ өөрчилж алхаж, гүйнэ. | L5: СҮД: ХЭМ1.1е. Дөрвөн хөллөж 20 см-ын зайтай зураасны хооронд мөлхөнө. | N5: СҮД: ХЭМ1.1и. Хоёр хөл дээр байрандаа үсэрч бууна. | P5: СҮД: ХЭМ1.1м. Бөмбөгийг ойр зайд шидэж дамжуулна, барьж авна. | R5: СҮД: ХЭМ1.2а. Хувийн ариун цэврийг сахих үйлийг насанд хүрэгчийн дэмжлэгтэйгээр хамтран хийнэ. | T5: СҮД: ХЭМ1.2г. Хоолны хэрэгслийг нэрлэж, зориулалтын дагуу хэрэглэнэ.
D6: Хүүхдийн хийх үйл: | F6: Хүүхдийн хийх үйл: | H6: Хүүхдийн хийх үйл: | J6: Хүүхдийн хийх үйл: | L6: Хүүхдийн хийх үйл: | N6: Хүүхдийн хийх үйл: | P6: Хүүхдийн хийх үйл: | R6: Хүүхдийн хийх үйл: | T6: Хүүхдийн хийх үйл:
D7: Түүхий төмс, луувангийн зургийг харуулахад «идэж болохгүй, чанана» гэж хэлж эсвэл заадаг. | F7: Халуун данх, хутга, залгуурын зургийг зааж «болохгүй» гэдэг. | H7: 10 м зайд тавьсан 1–2 саадыг тойрч алхдаг. | J7: 20 см зайтай хоёр зураасны дундуур шулуун гүйдэг. | L7: 20 см зайтай зураасны хооронд дөрвөн хөллөж мөлхдөг. | N7: Хоёр хөлөөрөө байрандаа үсэрч, хөл дээрээ буудаг. | P7: Бөмбөг, базсан цаасыг урагш эсвэл дээш шидэж дамжуулдаг. | R7: Багшийн дэмжлэгтэй гар, нүүрээ угааж, амаа зайлдаг. | T7: Халбага, аягыг зориулалтаар нь барьж хооллодог.
D8: Шалгуур №1 | F8: Шалгуур №2 | H8: Шалгуур №12 | J8: Шалгуур №13 | L8: Шалгуур №14 | N8: Шалгуур №15 | P8: Шалгуур №16 | R8: Шалгуур №17 | T8: Шалгуур №18
D9: Чадна | E9: Чадахгүй | F9: Чадна | G9: Чадахгүй | H9: Чадна | I9: Чадахгүй | J9: Чадна | K9: Чадахгүй | L9: Чадна | M9: Чадахгүй | N9: Чадна | O9: Чадахгүй | P9: Чадна | Q9: Чадахгүй | R9: Чадна | S9: Чадахгүй | T9: Чадна | U9: Чадахгүй
A10: 1 | B10: =IF(Нэгтгэл!B7="","",Нэгтгэл!B7) | V10: =SUM(D10,F10,H10,J10,L10,N10,P10,R10,T10) | W10: =IF(V10+X10=0,"",ROUND(V10/9*100,1)) | X10: =SUM(E10,G10,I10,K10,M10,O10,Q10,S10,U10) | Y10: =IF(V10+X10=0,"",ROUND(X10/9*100,1)) | Z10: =IF(W10="","",IF(W10>=80,"Хангалттай эзэмшиж байна",IF(W10>=50,"Ахиж байна","Хөгжиж байна")))
A11: 2 | B11: =IF(Нэгтгэл!B8="","",Нэгтгэл!B8) | V11: =SUM(D11,F11,H11,J11,L11,N11,P11,R11,T11) | W11: =IF(V11+X11=0,"",ROUND(V11/9*100,1)) | X11: =SUM(E11,G11,I11,K11,M11,O11,Q11,S11,U11) | Y11: =IF(V11+X11=0,"",ROUND(X11/9*100,1)) | Z11: =IF(W11="","",IF(W11>=80,"Хангалттай эзэмшиж байна",IF(W11>=50,"Ахиж байна","Хөгжиж байна")))
A12: 3 | B12: =IF(Нэгтгэл!B9="","",Нэгтгэл!B9) | V12: =SUM(D12,F12,H12,J12,L12,N12,P12,R12,T12) | W12: =IF(V12+X12=0,"",ROUND(V12/9*100,1)) | X12: =SUM(E12,G12,I12,K12,M12,O12,Q12,S12,U12) | Y12: =IF(V12+X12=0,"",ROUND(X12/9*100,1)) | Z12: =IF(W12="","",IF(W12>=80,"Хангалттай эзэмшиж байна",IF(W12>=50,"Ахиж байна","Хөгжиж байна")))
A13: 4 | B13: =IF(Нэгтгэл!B10="","",Нэгтгэл!B10) | V13: =SUM(D13,F13,H13,J13,L13,N13,P13,R13,T13) | W13: =IF(V13+X13=0,"",ROUND(V13/9*100,1)) | X13: =SUM(E13,G13,I13,K13,M13,O13,Q13,S13,U13) | Y13: =IF(V13+X13=0,"",ROUND(X13/9*100,1)) | Z13: =IF(W13="","",IF(W13>=80,"Хангалттай эзэмшиж байна",IF(W13>=50,"Ахиж байна","Хөгжиж байна")))
A14: 5 | B14: =IF(Нэгтгэл!B11="","",Нэгтгэл!B11) | V14: =SUM(D14,F14,H14,J14,L14,N14,P14,R14,T14) | W14: =IF(V14+X14=0,"",ROUND(V14/9*100,1)) | X14: =SUM(E14,G14,I14,K14,M14,O14,Q14,S14,U14) | Y14: =IF(V14+X14=0,"",ROUND(X14/9*100,1)) | Z14: =IF(W14="","",IF(W14>=80,"Хангалттай эзэмшиж байна",IF(W14>=50,"Ахиж байна","Хөгжиж байна")))
A15: 6 | B15: =IF(Нэгтгэл!B12="","",Нэгтгэл!B12) | V15: =SUM(D15,F15,H15,J15,L15,N15,P15,R15,T15) | W15: =IF(V15+X15=0,"",ROUND(V15/9*100,1)) | X15: =SUM(E15,G15,I15,K15,M15,O15,Q15,S15,U15) | Y15: =IF(V15+X15=0,"",ROUND(X15/9*100,1)) | Z15: =IF(W15="","",IF(W15>=80,"Хангалттай эзэмшиж байна",IF(W15>=50,"Ахиж байна","Хөгжиж байна")))
A16: 7 | B16: =IF(Нэгтгэл!B13="","",Нэгтгэл!B13) | V16: =SUM(D16,F16,H16,J16,L16,N16,P16,R16,T16) | W16: =IF(V16+X16=0,"",ROUND(V16/9*100,1)) | X16: =SUM(E16,G16,I16,K16,M16,O16,Q16,S16,U16) | Y16: =IF(V16+X16=0,"",ROUND(X16/9*100,1)) | Z16: =IF(W16="","",IF(W16>=80,"Хангалттай эзэмшиж байна",IF(W16>=50,"Ахиж байна","Хөгжиж байна")))
A17: 8 | B17: =IF(Нэгтгэл!B14="","",Нэгтгэл!B14) | V17: =SUM(D17,F17,H17,J17,L17,N17,P17,R17,T17) | W17: =IF(V17+X17=0,"",ROUND(V17/9*100,1)) | X17: =SUM(E17,G17,I17,K17,M17,O17,Q17,S17,U17) | Y17: =IF(V17+X17=0,"",ROUND(X17/9*100,1)) | Z17: =IF(W17="","",IF(W17>=80,"Хангалттай эзэмшиж байна",IF(W17>=50,"Ахиж байна","Хөгжиж байна")))
A18: 9 | B18: =IF(Нэгтгэл!B15="","",Нэгтгэл!B15) | V18: =SUM(D18,F18,H18,J18,L18,N18,P18,R18,T18) | W18: =IF(V18+X18=0,"",ROUND(V18/9*100,1)) | X18: =SUM(E18,G18,I18,K18,M18,O18,Q18,S18,U18) | Y18: =IF(V18+X18=0,"",ROUND(X18/9*100,1)) | Z18: =IF(W18="","",IF(W18>=80,"Хангалттай эзэмшиж байна",IF(W18>=50,"Ахиж байна","Хөгжиж байна")))
A19: 10 | B19: =IF(Нэгтгэл!B16="","",Нэгтгэл!B16) | V19: =SUM(D19,F19,H19,J19,L19,N19,P19,R19,T19) | W19: =IF(V19+X19=0,"",ROUND(V19/9*100,1)) | X19: =SUM(E19,G19,I19,K19,M19,O19,Q19,S19,U19) | Y19: =IF(V19+X19=0,"",ROUND(X19/9*100,1)) | Z19: =IF(W19="","",IF(W19>=80,"Хангалттай эзэмшиж байна",IF(W19>=50,"Ахиж байна","Хөгжиж байна")))
A20: 11 | B20: =IF(Нэгтгэл!B17="","",Нэгтгэл!B17) | V20: =SUM(D20,F20,H20,J20,L20,N20,P20,R20,T20) | W20: =IF(V20+X20=0,"",ROUND(V20/9*100,1)) | X20: =SUM(E20,G20,I20,K20,M20,O20,Q20,S20,U20) | Y20: =IF(V20+X20=0,"",ROUND(X20/9*100,1)) | Z20: =IF(W20="","",IF(W20>=80,"Хангалттай эзэмшиж байна",IF(W20>=50,"Ахиж байна","Хөгжиж байна")))
A21: 12 | B21: =IF(Нэгтгэл!B18="","",Нэгтгэл!B18) | V21: =SUM(D21,F21,H21,J21,L21,N21,P21,R21,T21) | W21: =IF(V21+X21=0,"",ROUND(V21/9*100,1)) | X21: =SUM(E21,G21,I21,K21,M21,O21,Q21,S21,U21) | Y21: =IF(V21+X21=0,"",ROUND(X21/9*100,1)) | Z21: =IF(W21="","",IF(W21>=80,"Хангалттай эзэмшиж байна",IF(W21>=50,"Ахиж байна","Хөгжиж байна")))
... A39: 30 | B39: =IF(Нэгтгэл!B36="","",Нэгтгэл!B36) | V39: =SUM(D39,F39,H39,J39,L39,N39,P39,R39,T39) | W39: =IF(V39+X39=0,"",ROUND(V39/9*100,1)) | X39: =SUM(E39,G39,I39,K39,M39,O39,Q39,S39,U39) | Y39: =IF(V39+X39=0,"",ROUND(X39/9*100,1)) | Z39: =IF(W39="","",IF(W39>=80,"Хангалттай эзэмшиж байна",IF(W39>=50,"Ахиж байна","Хөгжиж байна")))
